Workbook
Name DA_x1data: INDIRECT("'" &"Double Analysis" &"'" &"!" & ADDRESS(Guts!$D$38,1)):INDIRECT("'" &"Double Analysis" &"'" &"!" & ADDRESS(Guts!$D$35,1))
Name DA_x2data: INDIRECT("'" &"Double Analysis" &"'" &"!" & ADDRESS(Guts!$D$44,4)):INDIRECT("'" &"Double Analysis" &"'" &"!" & ADDRESS(Guts!$D$41,4))
Name DA_y1data: INDIRECT("'" &"Double Analysis" &"'" &"!" & ADDRESS(Guts!$D$38,2)):INDIRECT("'" &"Double Analysis" &"'" &"!" & ADDRESS(Guts!$D$35,2))
Name DA_y2data: INDIRECT("'" &"Double Analysis" &"'" &"!" & ADDRESS(Guts!$D$44,5)):INDIRECT("'" &"Double Analysis" &"'" &"!" & ADDRESS(Guts!$D$41,5))
Name mf_xData: INDIRECT("'" &"Manual Fitting" &"'" &"!" & ADDRESS(Guts!$D$68,1)):INDIRECT("'" &"Manual Fitting" &"'" &"!" & ADDRESS(Guts!$D$65,1))
Name mf_yData: INDIRECT("'" &"Manual Fitting" &"'" &"!" & ADDRESS(Guts!$D$68,2)):INDIRECT("'" &"Manual Fitting" &"'" &"!" & ADDRESS(Guts!$D$65,2))
Name solver_adj: Guts!$AI$15:$AI$17
Name solver_cvg: 0.0001
Name solver_drv: 1
Name solver_eng: 1
Name solver_eng: 1
Name solver_itr: 2147483647
Name solver_lin: 2
Name solver_lin: 2
Name solver_mip: 2147483647
Name solver_mni: 30
Name solver_mrt: 0.075
Name solver_msl: 2
Name solver_neg: 1
Name solver_neg: 1
Name solver_nod: 2147483647
Name solver_num: 0
Name solver_num: 0
Name solver_opt: Analysis!$A$7
Name solver_opt: Guts!$AQ$104
Name solver_pre: 0.000001
Name solver_rbv: 1
Name solver_rlx: 2
Name solver_rsd: 0
Name solver_scl: 1
Name solver_sho: 2
Name solver_ssz: 100
Name solver_tim: 2147483647
Name solver_tol: 0.01
Name solver_typ: 1
Name solver_typ: 2
Name solver_val: 0
Name solver_val: 0
Name solver_ver: 2
Name solver_ver: 2
Name x1Data: INDIRECT("'"&"Analysis"&"'"&"!"&ADDRESS(Guts!$D$7,1)):INDIRECT("'"&"Analysis"&"'"&"!"&ADDRESS(Guts!$D$4,1))
Name xtograph: Guts!$N$2:INDIRECT("'"&"Guts"&"'"&"!"&ADDRESS(Guts!$A$60,14))
Name y1Data: INDIRECT("'"&"Analysis"&"'"&"!"&ADDRESS(Guts!$D$7,2)):INDIRECT("'"&"Analysis"&"'"&"!"&ADDRESS(Guts!$D$4,2))
Name ytograph: Guts!$O$2:INDIRECT("'"&"Guts"&"'"&"!"&ADDRESS(Guts!$A$60,15))

Sheet Analysis
A1: Applied Force (lbs) | B1: Strain gauge Differential Voltage (mV)
A2: 0 | B2: 0
A3: 1000 | B3: 4.18
A4: 2000 | B4: 7.74
A5: 3000 | B5: 11.36
A6: 4000 | B6: 15.08
A7: 5000 | B7: 18.72
A8: 6000 | B8: 22.36
A9: 7000 | B9: 26.12
A10: 8000 | B10: 30.01
A11: 7000 | B11: 27.13
A12: 6000 | B12: 23.12
A13: 5000 | B13: 20.06
... A18: 0 | B18: 0.7
A22: Applied Force (lbs) | B22: Differential amplified Voltage (V)
A23: 0 | B23: 1.42
A24: 1000 | B24: 1.52
A25: 2000 | B25: 1.68
A26: 3000 | B26: 1.84
A27: 4000 | B27: 2
A28: 5000 | B28: 2.16
A29: 6000 | B29: 2.32
A30: 7000 | B30: 2.49
A31: 8000 | B31: 2.63
A32: 8000 | B32: 2.64
A33: 7000 | B33: 2.56
A34: 6000 | B34: 2.35
... A40: 0 | B40: 1.42

Sheet Double Analysis
A1: Name: | I1: =TODAY() -> 46043
A2: First Dataset | D2: Second Dataset
A3: X Values | B3: Y Values | D3: =A3 -> X Values | E3: =B3 -> Y Values | J3: Fit Equation:
J4: {=IF(Guts!D32=4, INDEX(Guts!E23:E27,G13+1), INDEX({"y=A+Bx","y=A+Bx+Cx²","y=A+Bx+Cx²+Dx³"," ","y=Axᴮ","y=Aeᴮˣ","No Fitting"},Guts!D32))} -> y=A+Bx+Cx²
H6: First Dataset Fit
I7: Value | J7: Uncertainty | K7: CD: | L7: =IFERROR(Guts!B50, "No fit") -> 0
H8: =IF(Guts!$D$32=4,MID("ABCDE",$G$13+1,1),IF(Guts!$D$32=7," ","A")) -> A | I8: =IF(OR(Guts!D32=5,Guts!D32=6),IFERROR(EXP(Guts!$C$48), "Error: Check for negative values"),IFERROR(IF(Guts!D32=1,Guts!$C$48,IF(Guts!D32=4,Guts!$B$48,IF(Guts!D32=2,Guts!$D$48,IF(Guts!D32=3,Guts!$E$48," ")))),"")) -> 0 | J8: =IF(OR(Guts!D32=5, Guts!D32=6),IFERROR(I8*Guts!$C$49,""),IFERROR(IF(Guts!D32=1,Guts!$C$49,IF(Guts!D32=4,Guts!$B$49,IF(Guts!D32=2,Guts!$D$49,IF(Guts!D32=3,Guts!$E$49," ")))),"")) -> 0
H9: =IF(Guts!$D$32=4," ",IF(Guts!$D$32=7," ","B")) -> B | I9: =IF(OR(Guts!D32=5, Guts!D32=6),IFERROR(Guts!$B$48,"Error, check for negative values"),IFERROR(IF(Guts!D32=1,Guts!$B$48,IF(Guts!D32=2,Guts!$C$48,IF(Guts!D32=3,Guts!$D$48," ")))," ")) -> 0 | J9: =IF(OR(Guts!D32=5, Guts!D32=6),IFERROR(Guts!$B$49," "),IFERROR(IF(Guts!D32=1,Guts!$B$49,IF(Guts!D32=2,Guts!$C$49,IF(Guts!D32=3,Guts!$D$49," ")))," ")) -> 0
H10: =IF(OR(Guts!$D$32=2,Guts!$D$32=3),"C"," ") -> C | I10: =IFERROR(IF(Guts!$D$32=2,Guts!$B$48,IF(Guts!$D$32=3,Guts!$C$48," "))," ") | J10: =IFERROR(IF(Guts!$D$32=2,Guts!$B$49,IF(Guts!$D$32=3,Guts!$C$49," "))," ") -> 0
H11: =IF(Guts!$D$32=3,"D"," ") | I11: =IFERROR(IF(Guts!$D$32=3,Guts!$B$48," ")," ") | J11: =IFERROR(IF(Guts!$D$32=3,Guts!$B$49," ")," ")
F12: Power for fixed power fit:
G13: 1 | H13: Second Dataset Fit
I14: Value | J14: Uncertainty | K14: CD: | L14: =IFERROR(Guts!B56, "No fit") -> 0
H15: =H8 -> A | I15: =IF(OR(Guts!D32=5,Guts!D32=6),IFERROR(EXP(Guts!$C$54), "Error: Check for negative values"),IFERROR(IF(Guts!D32=1,Guts!$C$54,IF(Guts!D32=4,Guts!$B$54,IF(Guts!D32=2,Guts!$D$54,IF(Guts!D32=3,Guts!$E$54," ")))),"")) -> 0 | J15: =IF(OR(Guts!D32=5, Guts!D32=6),IFERROR(I15*Guts!$C$55,""),IFERROR(IF(Guts!D32=1,Guts!$C$55,IF(Guts!D32=4,Guts!$B$55,IF(Guts!D32=2,Guts!$D$55,IF(Guts!D32=3,Guts!$E$55," ")))),"")) -> 0
H16: =H9 -> B | I16: =IF(OR(Guts!D32=5, Guts!D32=6),IFERROR(Guts!$B$54,"Error, check for negative values"),IFERROR(IF(Guts!D32=1,Guts!$B$54,IF(Guts!D32=2,Guts!$C$54,IF(Guts!D32=3,Guts!$D$54," ")))," ")) -> 0 | J16: =IF(OR(Guts!D32=5, Guts!D32=6),IFERROR(Guts!$B$55," "),IFERROR(IF(Guts!D32=1,Guts!$B$55,IF(Guts!D32=2,Guts!$C$55,IF(Guts!D32=3,Guts!$D$55," ")))," ")) -> 0
H17: =H10 -> C | I17: =IFERROR(IF(Guts!$D$32=2,Guts!$B$54,IF(Guts!$D$32=3,Guts!$C$54," "))," ") | J17: =IFERROR(IF(Guts!$D$32=2,Guts!$B$55,IF(Guts!$D$32=3,Guts!$C$55," "))," ") -> 0
H18: =H11 | I18: =IFERROR(IF(Guts!$D$32=3,Guts!$B$54," ")," ") | J18: =IFERROR(IF(Guts!$D$32=3,Guts!$B$55," ")," ")

Sheet Comparison
A1: Name: | E1: =TODAY() -> 46043
A3: № | B3: Source | C3: Value (unit) | D3: Uncertainty
A4: 1
A5: 2
A6: 3
A7: 4
A8: 5
A9: 6

Sheet Manual Fitting
A1: Name: | I1: =TODAY() -> 46043
A2: X Values | B2: Y Values
C23: Fit Type | G23: Fit Function
G24: {=INDEX(Guts!AI5:AI8,Guts!AI1)} -> y=A+Bx
G27: Parameter | H27: Manual Estimate | J27: CD: | K27: =IF(Guts!AP104=0," ",IF((Guts!AQ104)/(Guts!AR104)<1,1-(Guts!AQ104)/(Guts!AR104),"below 0%"))
G28: A | H28: 0
G29: B | H29: 0.04
G30: =IF(Guts!$AI$1<>1,"C","")
G31: =IF(Guts!$AI$1=4,"D","")

Sheet Guts
A1: Fit type | D1: 8 | G1: x-values | H1: fit y-values | J1: DA x-values | K1: fit 1 y-values | L1: fit 2 y-values | N1: x-data | O1: y-data | P1: freeform y | Q1: w/ duplicates | R1: de-duplicated | T1: DAx1data | U1: DAy1data | V1: DAx2data | W1: DAy2data | Y1: DAx1 | Z1: DAx1 order | AA1: DAy1 match | AB1: Frform DAy1 | AC1: DAx2 | AD1: DAx2 order | AE1: DAy2 match | AF1: Frform DAy2 | AH1: Fit type | AI1: 1 | AK1: m.f. x-plot | AL1: m.f. fit y | AN1: m.f. xData | AO1: m.f. yData | AP1: m.f. y fit | AQ1: m.f. sq res | AR1: (y_i-y_av)^2
A2: Last row with x data | D2: {=LOOKUP(2,1/ISNUMBER(Analysis!A:A),ROW(Analysis!A:A))} -> 40 | F2: 0 | G2: =MIN(x1Data)+(MAX(x1Data)-MIN(x1Data))*(F2/100) -> 0 | H2: =IF($D$1=1,$C$11+$B$11*G2, IF($D$1=2,$B$11*G2^#REF!,IF($D$1=3,$D$11+$C$11*G2+$B$11*(G2)^2,IF($D$1=4,$E$11+$D$11*G2+$C$11*(G2)^2+$B$11*(G2)^3,IF($D$1=5,EXP($C$11)*G2^($B$11),IF($D$1=6,EXP($C$11+G2*$B$11), NA())))))) -> #N/A | J2: =IFERROR(MIN(DA_x1data,DA_x2data)+(MAX(DA_x1data,DA_x2data)-MIN(DA_x1data,DA_x2data))*(F2/100), MIN(DA_x1data)+(MAX(DA_x1data)-MIN(DA_x1data))*(F2/100)) -> #N/A | K2: =IF($D$32=1,$B$48*J2+$C$48,IF($D$32=2,$B$48*J2^2+$C$48*J2+$D$48,IF($D$32=3,$B$48*J2^3+$C$48*J2^2+$D$48*J2+$E$48,IF($D$32=4,$B$48*J2^'Double Analysis'!$G$13,IF($D$32=5,EXP($C$48)*J2^$B$48,IF($D$32=6,EXP($C$48+J2*$B$48),NA())))))) -> #N/A | L2: =IF($D$32=1,$B$54*J2+$C$54,IF($D$32=2,$B$54*J2^2+$C$54*J2+$D$54,IF($D$32=3,$B$54*J2^3+$C$54*J2^2+$D$54*J2+$E$54,IF($D$32=4,$B$54*J2^'Double Analysis'!$G$13,IF($D$32=5,EXP($C$54)*J2^$B$54,IF($D$32=6,EXP($C$54+J2*$B$54),NA())))))) -> #N/A | N2: =IFERROR(SMALL($R$2:$R$102, ROW()-1),NA()) -> 0 | O2: =IF(ISNUMBER(N2),INDEX(y1Data,MATCH(N2,$R$2:$R$102,0)),NA()) -> 0.7 | P2: =IF($D$1=7,O2,NA()) -> #N/A | Q2: {=IF(ISNUMBER(INDEX(x1Data,ROW()-1)),x1Data,"")} -> 0 | R2: =IF(Q2<>"",Q2+(0.0000000000001)*(COUNTIF($Q2:Q$102,Q2)-1),"") -> 1e-13 | T2: {=DA_x1data} -> #N/A | U2: {=DA_y1data} -> #N/A | V2: {=DA_x2data} -> #N/A | W2: {=DA_y2data} -> #N/A | Y2: =IF(ISNUMBER(T2),T2," ") | Z2: =IFERROR(SMALL($Y$2:$Y$102,ROW()-1),NA()) -> #N/A | AA2: {=IF(ISNUMBER(Z2),INDEX(DA_y1data,MATCH(Z2,$Y$2:$Y$102,0)),NA())} -> #N/A | AB2: =IF($D$32=7,AA2,NA()) -> #N/A | AC2: =IF(ISNUMBER(V2),V2," ") | AD2: =IFERROR(SMALL($AC$2:$AC$102,ROW()-1),NA()) -> #N/A | AE2: {=IF(ISNUMBER(AD2),INDEX(DA_y2data,MATCH(AD2,$AC$2:$AC$102,0)),NA())} -> #N/A | AF2: =IF($D$32=7,AE2,NA()) -> #N/A | AH2: Optimize? | AI2: 1 | AK2: =MIN('Manual Fitting'!$A$3:$A$32)+(MAX('Manual Fitting'!$A$3:$A$32)-MIN('Manual Fitting'!$A$3:$A$17))*(Guts!F2/100) -> 0 | AL2: =IF($AI$1=1,IF(AND(ISNUMBER($AH$15),ISNUMBER($AH$16)),$AH$15+AK2*$AH$16,NA()),IF($AI$1=2,IF(AND(ISNUMBER($AH$15),ISNUMBER($AH$16),ISNUMBER($AH$17)),$AH$15/(1+((AK2-$AH$16)/$AH$17)^2),NA()),IF($AI$1=3,IF(AND(ISNUMBER($AH$15),ISNUMBER($AH$16),ISNUMBER($AH$17)),$AH$15*EXP((-1)*((AK2-$AH$16)/$AH$17)^2),NA()), IF($AI$1=4,IF(AND(ISNUMBER($AH$15),ISNUMBER($AH$16),ISNUMBER($AH$17),ISNUMBER($AH$18)),$AH$15*SIN((AK2*$AH$16)-$AH$17)+$AH$18,NA()),NA())))) -> 0 | AN2: {=mf_xData} -> #N/A | AO2: {=mf_yData} -> #N/A | AP2: =IF($AI$1=1,IF(AND(ISNUMBER($AH$15),ISNUMBER($AH$16)),$AH$15+AN2*$AH$16,NA()),IF($AI$1=2,IF(AND(ISNUMBER($AH$15),ISNUMBER($AH$16),ISNUMBER($AH$17)),$AH$15/(1+((AN2-$AH$16)/$AH$17)^2),NA()), IF($AI$1=3,IF(AND(ISNUMBER($AH$15),ISNUMBER($AH$16),ISNUMBER($AH$17)),$AH$15*EXP(-(((AN2-$AH$16)/$AH$17)^2)),NA()),IF($AI$1=4,IF(AND(ISNUMBER($AH$15),ISNUMBER($AH$16),ISNUMBER($AH$17),ISNUMBER($AH$18)),$AH$15*SIN($AH$16*AN2-$AH$17)+$AH$18,NA()),NA())))) -> #N/A | AQ2: =(AP2-AO2)^2 -> #N/A | AR2: =(AO2-$AO$104)^2 -> #N/A
A3: Last row with y data | D3: {=LOOKUP(2,1/ISNUMBER(Analysis!B:B),ROW(Analysis!B:B))} -> 40 | F3: 1 | G3: =MIN(x1Data)+(MAX(x1Data)-MIN(x1Data))*(F3/100) -> 80 | H3: =IF($D$1=1,$C$11+$B$11*G3, IF($D$1=2,$B$11*G3^#REF!,IF($D$1=3,$D$11+$C$11*G3+$B$11*(G3)^2,IF($D$1=4,$E$11+$D$11*G3+$C$11*(G3)^2+$B$11*(G3)^3,IF($D$1=5,EXP($C$11)*G3^($B$11),IF($D$1=6,EXP($C$11+G3*$B$11), NA())))))) -> #N/A | J3: =IFERROR(MIN(DA_x1data,DA_x2data)+(MAX(DA_x1data,DA_x2data)-MIN(DA_x1data,DA_x2data))*(F3/100), MIN(DA_x1data)+(MAX(DA_x1data)-MIN(DA_x1data))*(F3/100)) -> #N/A | K3: =IF($D$32=1,$B$48*J3+$C$48,IF($D$32=2,$B$48*J3^2+$C$48*J3+$D$48,IF($D$32=3,$B$48*J3^3+$C$48*J3^2+$D$48*J3+$E$48,IF($D$32=4,$B$48*J3^'Double Analysis'!$G$13,IF($D$32=5,EXP($C$48)*J3^$B$48,IF($D$32=6,EXP($C$48+J3*$B$48),NA())))))) -> #N/A | L3: =IF($D$32=1,$B$54*J3+$C$54,IF($D$32=2,$B$54*J3^2+$C$54*J3+$D$54,IF($D$32=3,$B$54*J3^3+$C$54*J3^2+$D$54*J3+$E$54,IF($D$32=4,$B$54*J3^'Double Analysis'!$G$13,IF($D$32=5,EXP($C$54)*J3^$B$54,IF($D$32=6,EXP($C$54+J3*$B$54),NA())))))) -> #N/A | N3: =IFERROR(SMALL($R$2:$R$102, ROW()-1),NA()) -> 1e-13 | O3: =IF(ISNUMBER(N3),INDEX(y1Data,MATCH(N3,$R$2:$R$102,0)),NA()) -> 0 | P3: =IF($D$1=7,O3,NA()) -> #N/A | Q3: 1000 | R3: =IF(Q3<>"",Q3+(0.0000000000001)*(COUNTIF($Q3:Q$102,Q3)-1),"") -> 1000 | Y3: =IF(ISNUMBER(T3),T3," ") | Z3: =IFERROR(SMALL($Y$2:$Y$102,ROW()-1),NA()) -> #N/A | AA3: {=IF(ISNUMBER(Z3),INDEX(DA_y1data,MATCH(Z3,$Y$2:$Y$102,0)),NA())} -> #N/A | AB3: =IF($D$32=7,AA3,NA()) -> #N/A | AC3: =IF(ISNUMBER(V3),V3," ") | AD3: =IFERROR(SMALL($AC$2:$AC$102,ROW()-1),NA()) -> #N/A | AE3: {=IF(ISNUMBER(AD3),INDEX(DA_y2data,MATCH(AD3,$AC$2:$AC$102,0)),NA())} -> #N/A | AF3: =IF($D$32=7,AE3,NA()) -> #N/A | AK3: =MIN('Manual Fitting'!$A$3:$A$32)+(MAX('Manual Fitting'!$A$3:$A$32)-MIN('Manual Fitting'!$A$3:$A$17))*(Guts!F3/100) -> 0 | AL3: =IF($AI$1=1,IF(AND(ISNUMBER($AH$15),ISNUMBER($AH$16)),$AH$15+AK3*$AH$16,NA()),IF($AI$1=2,IF(AND(ISNUMBER($AH$15),ISNUMBER($AH$16),ISNUMBER($AH$17)),$AH$15/(1+((AK3-$AH$16)/$AH$17)^2),NA()),IF($AI$1=3,IF(AND(ISNUMBER($AH$15),ISNUMBER($AH$16),ISNUMBER($AH$17)),$AH$15*EXP((-1)*((AK3-$AH$16)/$AH$17)^2),NA()), IF($AI$1=4,IF(AND(ISNUMBER($AH$15),ISNUMBER($AH$16),ISNUMBER($AH$17),ISNUMBER($AH$18)),$AH$15*SIN((AK3*$AH$16)-$AH$17)+$AH$18,NA()),NA())))) -> 0 | AP3: =IF($AI$1=1,IF(AND(ISNUMBER($AH$15),ISNUMBER($AH$16)),$AH$15+AN3*$AH$16,NA()),IF($AI$1=2,IF(AND(ISNUMBER($AH$15),ISNUMBER($AH$16),ISNUMBER($AH$17)),$AH$15/(1+((AN3-$AH$16)/$AH$17)^2),NA()), IF($AI$1=3,IF(AND(ISNUMBER($AH$15),ISNUMBER($AH$16),ISNUMBER($AH$17)),$AH$15*EXP(-(((AN3-$AH$16)/$AH$17)^2)),NA()),IF($AI$1=4,IF(AND(ISNUMBER($AH$15),ISNUMBER($AH$16),ISNUMBER($AH$17),ISNUMBER($AH$18)),$AH$15*SIN($AH$16*AN3-$AH$17)+$AH$18,NA()),NA())))) -> 0 | AQ3: =(AP3-AO3)^2 -> 0 | AR3: =(AO3-$AO$104)^2 -> #N/A
A4: Last row with paired data | D4: =MIN(D2,D3) -> 40 | F4: 2 | G4: =MIN(x1Data)+(MAX(x1Data)-MIN(x1Data))*(F4/100) -> 160 | H4: =IF($D$1=1,$C$11+$B$11*G4, IF($D$1=2,$B$11*G4^#REF!,IF($D$1=3,$D$11+$C$11*G4+$B$11*(G4)^2,IF($D$1=4,$E$11+$D$11*G4+$C$11*(G4)^2+$B$11*(G4)^3,IF($D$1=5,EXP($C$11)*G4^($B$11),IF($D$1=6,EXP($C$11+G4*$B$11), NA())))))) -> #N/A | J4: =IFERROR(MIN(DA_x1data,DA_x2data)+(MAX(DA_x1data,DA_x2data)-MIN(DA_x1data,DA_x2data))*(F4/100), MIN(DA_x1data)+(MAX(DA_x1data)-MIN(DA_x1data))*(F4/100)) -> #N/A | K4: =IF($D$32=1,$B$48*J4+$C$48,IF($D$32=2,$B$48*J4^2+$C$48*J4+$D$48,IF($D$32=3,$B$48*J4^3+$C$48*J4^2+$D$48*J4+$E$48,IF($D$32=4,$B$48*J4^'Double Analysis'!$G$13,IF($D$32=5,EXP($C$48)*J4^$B$48,IF($D$32=6,EXP($C$48+J4*$B$48),NA())))))) -> #N/A | L4: =IF($D$32=1,$B$54*J4+$C$54,IF($D$32=2,$B$54*J4^2+$C$54*J4+$D$54,IF($D$32=3,$B$54*J4^3+$C$54*J4^2+$D$54*J4+$E$54,IF($D$32=4,$B$54*J4^'Double Analysis'!$G$13,IF($D$32=5,EXP($C$54)*J4^$B$54,IF($D$32=6,EXP($C$54+J4*$B$54),NA())))))) -> #N/A | N4: =IFERROR(SMALL($R$2:$R$102, ROW()-1),NA()) -> 1000 | O4: =IF(ISNUMBER(N4),INDEX(y1Data,MATCH(N4,$R$2:$R$102,0)),NA()) -> 5.22 | P4: =IF($D$1=7,O4,NA()) -> #N/A | Q4: 2000 | R4: =IF(Q4<>"",Q4+(0.0000000000001)*(COUNTIF($Q4:Q$102,Q4)-1),"") -> 2000 | Y4: =IF(ISNUMBER(T4),T4," ") | Z4: =IFERROR(SMALL($Y$2:$Y$102,ROW()-1),NA()) -> #N/A | AA4: {=IF(ISNUMBER(Z4),INDEX(DA_y1data,MATCH(Z4,$Y$2:$Y$102,0)),NA())} -> #N/A | AB4: =IF($D$32=7,AA4,NA()) -> #N/A | AC4: =IF(ISNUMBER(V4),V4," ") | AD4: =IFERROR(SMALL($AC$2:$AC$102,ROW()-1),NA()) -> #N/A | AE4: {=IF(ISNUMBER(AD4),INDEX(DA_y2data,MATCH(AD4,$AC$2:$AC$102,0)),NA())} -> #N/A | AF4: =IF($D$32=7,AE4,NA()) -> #N/A | AK4: =MIN('Manual Fitting'!$A$3:$A$32)+(MAX('Manual Fitting'!$A$3:$A$32)-MIN('Manual Fitting'!$A$3:$A$17))*(Guts!F4/100) -> 0 | AL4: =IF($AI$1=1,IF(AND(ISNUMBER($AH$15),ISNUMBER($AH$16)),$AH$15+AK4*$AH$16,NA()),IF($AI$1=2,IF(AND(ISNUMBER($AH$15),ISNUMBER($AH$16),ISNUMBER($AH$17)),$AH$15/(1+((AK4-$AH$16)/$AH$17)^2),NA()),IF($AI$1=3,IF(AND(ISNUMBER($AH$15),ISNUMBER($AH$16),ISNUMBER($AH$17)),$AH$15*EXP((-1)*((AK4-$AH$16)/$AH$17)^2),NA()), IF($AI$1=4,IF(AND(ISNUMBER($AH$15),ISNUMBER($AH$16),ISNUMBER($AH$17),ISNUMBER($AH$18)),$AH$15*SIN((AK4*$AH$16)-$AH$17)+$AH$18,NA()),NA())))) -> 0 | AP4: =IF($AI$1=1,IF(AND(ISNUMBER($AH$15),ISNUMBER($AH$16)),$AH$15+AN4*$AH$16,NA()),IF($AI$1=2,IF(AND(ISNUMBER($AH$15),ISNUMBER($AH$16),ISNUMBER($AH$17)),$AH$15/(1+((AN4-$AH$16)/$AH$17)^2),NA()), IF($AI$1=3,IF(AND(ISNUMBER($AH$15),ISNUMBER($AH$16),ISNUMBER($AH$17)),$AH$15*EXP(-(((AN4-$AH$16)/$AH$17)^2)),NA()),IF($AI$1=4,IF(AND(ISNUMBER($AH$15),ISNUMBER($AH$16),ISNUMBER($AH$17),ISNUMBER($AH$18)),$AH$15*SIN($AH$16*AN4-$AH$17)+$AH$18,NA()),NA())))) -> 0 | AQ4: =(AP4-AO4)^2 -> 0 | AR4: =(AO4-$AO$104)^2 -> #N/A
A5: First row with x data | D5: {=MATCH(TRUE,ISNUMBER(Analysis!$A:$A),0)} -> 2 | F5: 3 | G5: =MIN(x1Data)+(MAX(x1Data)-MIN(x1Data))*(F5/100) -> 240 | H5: =IF($D$1=1,$C$11+$B$11*G5, IF($D$1=2,$B$11*G5^#REF!,IF($D$1=3,$D$11+$C$11*G5+$B$11*(G5)^2,IF($D$1=4,$E$11+$D$11*G5+$C$11*(G5)^2+$B$11*(G5)^3,IF($D$1=5,EXP($C$11)*G5^($B$11),IF($D$1=6,EXP($C$11+G5*$B$11), NA())))))) -> #N/A | J5: =IFERROR(MIN(DA_x1data,DA_x2data)+(MAX(DA_x1data,DA_x2data)-MIN(DA_x1data,DA_x2data))*(F5/100), MIN(DA_x1data)+(MAX(DA_x1data)-MIN(DA_x1data))*(F5/100)) -> #N/A | K5: =IF($D$32=1,$B$48*J5+$C$48,IF($D$32=2,$B$48*J5^2+$C$48*J5+$D$48,IF($D$32=3,$B$48*J5^3+$C$48*J5^2+$D$48*J5+$E$48,IF($D$32=4,$B$48*J5^'Double Analysis'!$G$13,IF($D$32=5,EXP($C$48)*J5^$B$48,IF($D$32=6,EXP($C$48+J5*$B$48),NA())))))) -> #N/A | L5: =IF($D$32=1,$B$54*J5+$C$54,IF($D$32=2,$B$54*J5^2+$C$54*J5+$D$54,IF($D$32=3,$B$54*J5^3+$C$54*J5^2+$D$54*J5+$E$54,IF($D$32=4,$B$54*J5^'Double Analysis'!$G$13,IF($D$32=5,EXP($C$54)*J5^$B$54,IF($D$32=6,EXP($C$54+J5*$B$54),NA())))))) -> #N/A | N5: =IFERROR(SMALL($R$2:$R$102, ROW()-1),NA()) -> 1000 | O5: =IF(ISNUMBER(N5),INDEX(y1Data,MATCH(N5,$R$2:$R$102,0)),NA()) -> 4.18 | P5: =IF($D$1=7,O5,NA()) -> #N/A | Q5: 3000 | R5: =IF(Q5<>"",Q5+(0.0000000000001)*(COUNTIF($Q5:Q$102,Q5)-1),"") -> 3000 | Y5: =IF(ISNUMBER(T5),T5," ") | Z5: =IFERROR(SMALL($Y$2:$Y$102,ROW()-1),NA()) -> #N/A | AA5: {=IF(ISNUMBER(Z5),INDEX(DA_y1data,MATCH(Z5,$Y$2:$Y$102,0)),NA())} -> #N/A | AB5: =IF($D$32=7,AA5,NA()) -> #N/A | AC5: =IF(ISNUMBER(V5),V5," ") | AD5: =IFERROR(SMALL($AC$2:$AC$102,ROW()-1),NA()) -> #N/A | AE5: {=IF(ISNUMBER(AD5),INDEX(DA_y2data,MATCH(AD5,$AC$2:$AC$102,0)),NA())} -> #N/A | AF5: =IF($D$32=7,AE5,NA()) -> #N/A | AH5: linear | AI5: y=A+Bx | AK5: =MIN('Manual Fitting'!$A$3:$A$32)+(MAX('Manual Fitting'!$A$3:$A$32)-MIN('Manual Fitting'!$A$3:$A$17))*(Guts!F5/100) -> 0 | AL5: =IF($AI$1=1,IF(AND(ISNUMBER($AH$15),ISNUMBER($AH$16)),$AH$15+AK5*$AH$16,NA()),IF($AI$1=2,IF(AND(ISNUMBER($AH$15),ISNUMBER($AH$16),ISNUMBER($AH$17)),$AH$15/(1+((AK5-$AH$16)/$AH$17)^2),NA()),IF($AI$1=3,IF(AND(ISNUMBER($AH$15),ISNUMBER($AH$16),ISNUMBER($AH$17)),$AH$15*EXP((-1)*((AK5-$AH$16)/$AH$17)^2),NA()), IF($AI$1=4,IF(AND(ISNUMBER($AH$15),ISNUMBER($AH$16),ISNUMBER($AH$17),ISNUMBER($AH$18)),$AH$15*SIN((AK5*$AH$16)-$AH$17)+$AH$18,NA()),NA())))) -> 0 | AP5: =IF($AI$1=1,IF(AND(ISNUMBER($AH$15),ISNUMBER($AH$16)),$AH$15+AN5*$AH$16,NA()),IF($AI$1=2,IF(AND(ISNUMBER($AH$15),ISNUMBER($AH$16),ISNUMBER($AH$17)),$AH$15/(1+((AN5-$AH$16)/$AH$17)^2),NA()), IF($AI$1=3,IF(AND(ISNUMBER($AH$15),ISNUMBER($AH$16),ISNUMBER($AH$17)),$AH$15*EXP(-(((AN5-$AH$16)/$AH$17)^2)),NA()),IF($AI$1=4,IF(AND(ISNUMBER($AH$15),ISNUMBER($AH$16),ISNUMBER($AH$17),ISNUMBER($AH$18)),$AH$15*SIN($AH$16*AN5-$AH$17)+$AH$18,NA()),NA())))) -> 0 | AQ5: =(AP5-AO5)^2 -> 0 | AR5: =(AO5-$AO$104)^2 -> #N/A
A6: First row with y data | D6: {=MATCH(TRUE,ISNUMBER(Analysis!$B:$B),0)} -> 2 | F6: 4 | G6: =MIN(x1Data)+(MAX(x1Data)-MIN(x1Data))*(F6/100) -> 320 | H6: =IF($D$1=1,$C$11+$B$11*G6, IF($D$1=2,$B$11*G6^#REF!,IF($D$1=3,$D$11+$C$11*G6+$B$11*(G6)^2,IF($D$1=4,$E$11+$D$11*G6+$C$11*(G6)^2+$B$11*(G6)^3,IF($D$1=5,EXP($C$11)*G6^($B$11),IF($D$1=6,EXP($C$11+G6*$B$11), NA())))))) -> #N/A | J6: =IFERROR(MIN(DA_x1data,DA_x2data)+(MAX(DA_x1data,DA_x2data)-MIN(DA_x1data,DA_x2data))*(F6/100), MIN(DA_x1data)+(MAX(DA_x1data)-MIN(DA_x1data))*(F6/100)) -> #N/A | K6: =IF($D$32=1,$B$48*J6+$C$48,IF($D$32=2,$B$48*J6^2+$C$48*J6+$D$48,IF($D$32=3,$B$48*J6^3+$C$48*J6^2+$D$48*J6+$E$48,IF($D$32=4,$B$48*J6^'Double Analysis'!$G$13,IF($D$32=5,EXP($C$48)*J6^$B$48,IF($D$32=6,EXP($C$48+J6*$B$48),NA())))))) -> #N/A | L6: =IF($D$32=1,$B$54*J6+$C$54,IF($D$32=2,$B$54*J6^2+$C$54*J6+$D$54,IF($D$32=3,$B$54*J6^3+$C$54*J6^2+$D$54*J6+$E$54,IF($D$32=4,$B$54*J6^'Double Analysis'!$G$13,IF($D$32=5,EXP($C$54)*J6^$B$54,IF($D$32=6,EXP($C$54+J6*$B$54),NA())))))) -> #N/A | N6: =IFERROR(SMALL($R$2:$R$102, ROW()-1),NA()) -> 2000 | O6: =IF(ISNUMBER(N6),INDEX(y1Data,MATCH(N6,$R$2:$R$102,0)),NA()) -> 7.74 | P6: =IF($D$1=7,O6,NA()) -> #N/A | Q6: 4000 | R6: =IF(Q6<>"",Q6+(0.0000000000001)*(COUNTIF($Q6:Q$102,Q6)-1),"") -> 4000 | Y6: =IF(ISNUMBER(T6),T6," ") | Z6: =IFERROR(SMALL($Y$2:$Y$102,ROW()-1),NA()) -> #N/A | AA6: {=IF(ISNUMBER(Z6),INDEX(DA_y1data,MATCH(Z6,$Y$2:$Y$102,0)),NA())} -> #N/A | AB6: =IF($D$32=7,AA6,NA()) -> #N/A | AC6: =IF(ISNUMBER(V6),V6," ") | AD6: =IFERROR(SMALL($AC$2:$AC$102,ROW()-1),NA()) -> #N/A | AE6: {=IF(ISNUMBER(AD6),INDEX(DA_y2data,MATCH(AD6,$AC$2:$AC$102,0)),NA())} -> #N/A | AF6: =IF($D$32=7,AE6,NA()) -> #N/A | AH6: lorentzian | AI6: y=A/(1+((x−B)/C)²) | AK6: =MIN('Manual Fitting'!$A$3:$A$32)+(MAX('Manual Fitting'!$A$3:$A$32)-MIN('Manual Fitting'!$A$3:$A$17))*(Guts!F6/100) -> 0 | AL6: =IF($AI$1=1,IF(AND(ISNUMBER($AH$15),ISNUMBER($AH$16)),$AH$15+AK6*$AH$16,NA()),IF($AI$1=2,IF(AND(ISNUMBER($AH$15),ISNUMBER($AH$16),ISNUMBER($AH$17)),$AH$15/(1+((AK6-$AH$16)/$AH$17)^2),NA()),IF($AI$1=3,IF(AND(ISNUMBER($AH$15),ISNUMBER($AH$16),ISNUMBER($AH$17)),$AH$15*EXP((-1)*((AK6-$AH$16)/$AH$17)^2),NA()), IF($AI$1=4,IF(AND(ISNUMBER($AH$15),ISNUMBER($AH$16),ISNUMBER($AH$17),ISNUMBER($AH$18)),$AH$15*SIN((AK6*$AH$16)-$AH$17)+$AH$18,NA()),NA())))) -> 0 | AP6: =IF($AI$1=1,IF(AND(ISNUMBER($AH$15),ISNUMBER($AH$16)),$AH$15+AN6*$AH$16,NA()),IF($AI$1=2,IF(AND(ISNUMBER($AH$15),ISNUMBER($AH$16),ISNUMBER($AH$17)),$AH$15/(1+((AN6-$AH$16)/$AH$17)^2),NA()), IF($AI$1=3,IF(AND(ISNUMBER($AH$15),ISNUMBER($AH$16),ISNUMBER($AH$17)),$AH$15*EXP(-(((AN6-$AH$16)/$AH$17)^2)),NA()),IF($AI$1=4,IF(AND(ISNUMBER($AH$15),ISNUMBER($AH$16),ISNUMBER($AH$17),ISNUMBER($AH$18)),$AH$15*SIN($AH$16*AN6-$AH$17)+$AH$18,NA()),NA())))) -> 0 | AQ6: =(AP6-AO6)^2 -> 0 | AR6: =(AO6-$AO$104)^2 -> #N/A
A7: First row with paired data | D7: =MAX(D5:D6) -> 2 | F7: 5 | G7: =MIN(x1Data)+(MAX(x1Data)-MIN(x1Data))*(F7/100) -> 400 | H7: =IF($D$1=1,$C$11+$B$11*G7, IF($D$1=2,$B$11*G7^#REF!,IF($D$1=3,$D$11+$C$11*G7+$B$11*(G7)^2,IF($D$1=4,$E$11+$D$11*G7+$C$11*(G7)^2+$B$11*(G7)^3,IF($D$1=5,EXP($C$11)*G7^($B$11),IF($D$1=6,EXP($C$11+G7*$B$11), NA())))))) -> #N/A | J7: =IFERROR(MIN(DA_x1data,DA_x2data)+(MAX(DA_x1data,DA_x2data)-MIN(DA_x1data,DA_x2data))*(F7/100), MIN(DA_x1data)+(MAX(DA_x1data)-MIN(DA_x1data))*(F7/100)) -> #N/A | K7: =IF($D$32=1,$B$48*J7+$C$48,IF($D$32=2,$B$48*J7^2+$C$48*J7+$D$48,IF($D$32=3,$B$48*J7^3+$C$48*J7^2+$D$48*J7+$E$48,IF($D$32=4,$B$48*J7^'Double Analysis'!$G$13,IF($D$32=5,EXP($C$48)*J7^$B$48,IF($D$32=6,EXP($C$48+J7*$B$48),NA())))))) -> #N/A | L7: =IF($D$32=1,$B$54*J7+$C$54,IF($D$32=2,$B$54*J7^2+$C$54*J7+$D$54,IF($D$32=3,$B$54*J7^3+$C$54*J7^2+$D$54*J7+$E$54,IF($D$32=4,$B$54*J7^'Double Analysis'!$G$13,IF($D$32=5,EXP($C$54)*J7^$B$54,IF($D$32=6,EXP($C$54+J7*$B$54),NA())))))) -> #N/A | N7: =IFERROR(SMALL($R$2:$R$102, ROW()-1),NA()) -> 2000 | O7: =IF(ISNUMBER(N7),INDEX(y1Data,MATCH(N7,$R$2:$R$102,0)),NA()) -> 7.74 | P7: =IF($D$1=7,O7,NA()) -> #N/A | Q7: 5000 | R7: =IF(Q7<>"",Q7+(0.0000000000001)*(COUNTIF($Q7:Q$102,Q7)-1),"") -> 5000 | Y7: =IF(ISNUMBER(T7),T7," ") | Z7: =IFERROR(SMALL($Y$2:$Y$102,ROW()-1),NA()) -> #N/A | AA7: {=IF(ISNUMBER(Z7),INDEX(DA_y1data,MATCH(Z7,$Y$2:$Y$102,0)),NA())} -> #N/A | AB7: =IF($D$32=7,AA7,NA()) -> #N/A | AC7: =IF(ISNUMBER(V7),V7," ") | AD7: =IFERROR(SMALL($AC$2:$AC$102,ROW()-1),NA()) -> #N/A | AE7: {=IF(ISNUMBER(AD7),INDEX(DA_y2data,MATCH(AD7,$AC$2:$AC$102,0)),NA())} -> #N/A | AF7: =IF($D$32=7,AE7,NA()) -> #N/A | AH7: gaussian | AI7: y=A exp(−((x−B)/C)²) | AK7: =MIN('Manual Fitting'!$A$3:$A$32)+(MAX('Manual Fitting'!$A$3:$A$32)-MIN('Manual Fitting'!$A$3:$A$17))*(Guts!F7/100) -> 0 | AL7: =IF($AI$1=1,IF(AND(ISNUMBER($AH$15),ISNUMBER($AH$16)),$AH$15+AK7*$AH$16,NA()),IF($AI$1=2,IF(AND(ISNUMBER($AH$15),ISNUMBER($AH$16),ISNUMBER($AH$17)),$AH$15/(1+((AK7-$AH$16)/$AH$17)^2),NA()),IF($AI$1=3,IF(AND(ISNUMBER($AH$15),ISNUMBER($AH$16),ISNUMBER($AH$17)),$AH$15*EXP((-1)*((AK7-$AH$16)/$AH$17)^2),NA()), IF($AI$1=4,IF(AND(ISNUMBER($AH$15),ISNUMBER($AH$16),ISNUMBER($AH$17),ISNUMBER($AH$18)),$AH$15*SIN((AK7*$AH$16)-$AH$17)+$AH$18,NA()),NA())))) -> 0 | AP7: =IF($AI$1=1,IF(AND(ISNUMBER($AH$15),ISNUMBER($AH$16)),$AH$15+AN7*$AH$16,NA()),IF($AI$1=2,IF(AND(ISNUMBER($AH$15),ISNUMBER($AH$16),ISNUMBER($AH$17)),$AH$15/(1+((AN7-$AH$16)/$AH$17)^2),NA()), IF($AI$1=3,IF(AND(ISNUMBER($AH$15),ISNUMBER($AH$16),ISNUMBER($AH$17)),$AH$15*EXP(-(((AN7-$AH$16)/$AH$17)^2)),NA()),IF($AI$1=4,IF(AND(ISNUMBER($AH$15),ISNUMBER($AH$16),ISNUMBER($AH$17),ISNUMBER($AH$18)),$AH$15*SIN($AH$16*AN7-$AH$17)+$AH$18,NA()),NA())))) -> 0 | AQ7: =(AP7-AO7)^2 -> 0 | AR7: =(AO7-$AO$104)^2 -> #N/A
F8: 6 | G8: =MIN(x1Data)+(MAX(x1Data)-MIN(x1Data))*(F8/100) -> 480 | H8: =IF($D$1=1,$C$11+$B$11*G8, IF($D$1=2,$B$11*G8^#REF!,IF($D$1=3,$D$11+$C$11*G8+$B$11*(G8)^2,IF($D$1=4,$E$11+$D$11*G8+$C$11*(G8)^2+$B$11*(G8)^3,IF($D$1=5,EXP($C$11)*G8^($B$11),IF($D$1=6,EXP($C$11+G8*$B$11), NA())))))) -> #N/A | J8: =IFERROR(MIN(DA_x1data,DA_x2data)+(MAX(DA_x1data,DA_x2data)-MIN(DA_x1data,DA_x2data))*(F8/100), MIN(DA_x1data)+(MAX(DA_x1data)-MIN(DA_x1data))*(F8/100)) -> #N/A | K8: =IF($D$32=1,$B$48*J8+$C$48,IF($D$32=2,$B$48*J8^2+$C$48*J8+$D$48,IF($D$32=3,$B$48*J8^3+$C$48*J8^2+$D$48*J8+$E$48,IF($D$32=4,$B$48*J8^'Double Analysis'!$G$13,IF($D$32=5,EXP($C$48)*J8^$B$48,IF($D$32=6,EXP($C$48+J8*$B$48),NA())))))) -> #N/A | L8: =IF($D$32=1,$B$54*J8+$C$54,IF($D$32=2,$B$54*J8^2+$C$54*J8+$D$54,IF($D$32=3,$B$54*J8^3+$C$54*J8^2+$D$54*J8+$E$54,IF($D$32=4,$B$54*J8^'Double Analysis'!$G$13,IF($D$32=5,EXP($C$54)*J8^$B$54,IF($D$32=6,EXP($C$54+J8*$B$54),NA())))))) -> #N/A | N8: =IFERROR(SMALL($R$2:$R$102, ROW()-1),NA()) -> 3000 | O8: =IF(ISNUMBER(N8),INDEX(y1Data,MATCH(N8,$R$2:$R$102,0)),NA()) -> 11.36 | P8: =IF($D$1=7,O8,NA()) -> #N/A | Q8: 6000 | R8: =IF(Q8<>"",Q8+(0.0000000000001)*(COUNTIF($Q8:Q$102,Q8)-1),"") -> 6000 | Y8: =IF(ISNUMBER(T8),T8," ") | Z8: =IFERROR(SMALL($Y$2:$Y$102,ROW()-1),NA()) -> #N/A | AA8: {=IF(ISNUMBER(Z8),INDEX(DA_y1data,MATCH(Z8,$Y$2:$Y$102,0)),NA())} -> #N/A | AB8: =IF($D$32=7,AA8,NA()) -> #N/A | AC8: =IF(ISNUMBER(V8),V8," ") | AD8: =IFERROR(SMALL($AC$2:$AC$102,ROW()-1),NA()) -> #N/A | AE8: {=IF(ISNUMBER(AD8),INDEX(DA_y2data,MATCH(AD8,$AC$2:$AC$102,0)),NA())} -> #N/A | AF8: =IF($D$32=7,AE8,NA()) -> #N/A | AH8: sine | AI8: y=A sin(Bx−C)+D | AK8: =MIN('Manual Fitting'!$A$3:$A$32)+(MAX('Manual Fitting'!$A$3:$A$32)-MIN('Manual Fitting'!$A$3:$A$17))*(Guts!F8/100) -> 0 | AL8: =IF($AI$1=1,IF(AND(ISNUMBER($AH$15),ISNUMBER($AH$16)),$AH$15+AK8*$AH$16,NA()),IF($AI$1=2,IF(AND(ISNUMBER($AH$15),ISNUMBER($AH$16),ISNUMBER($AH$17)),$AH$15/(1+((AK8-$AH$16)/$AH$17)^2),NA()),IF($AI$1=3,IF(AND(ISNUMBER($AH$15),ISNUMBER($AH$16),ISNUMBER($AH$17)),$AH$15*EXP((-1)*((AK8-$AH$16)/$AH$17)^2),NA()), IF($AI$1=4,IF(AND(ISNUMBER($AH$15),ISNUMBER($AH$16),ISNUMBER($AH$17),ISNUMBER($AH$18)),$AH$15*SIN((AK8*$AH$16)-$AH$17)+$AH$18,NA()),NA())))) -> 0 | AP8: =IF($AI$1=1,IF(AND(ISNUMBER($AH$15),ISNUMBER($AH$16)),$AH$15+AN8*$AH$16,NA()),IF($AI$1=2,IF(AND(ISNUMBER($AH$15),ISNUMBER($AH$16),ISNUMBER($AH$17)),$AH$15/(1+((AN8-$AH$16)/$AH$17)^2),NA()), IF($AI$1=3,IF(AND(ISNUMBER($AH$15),ISNUMBER($AH$16),ISNUMBER($AH$17)),$AH$15*EXP(-(((AN8-$AH$16)/$AH$17)^2)),NA()),IF($AI$1=4,IF(AND(ISNUMBER($AH$15),ISNUMBER($AH$16),ISNUMBER($AH$17),ISNUMBER($AH$18)),$AH$15*SIN($AH$16*AN8-$AH$17)+$AH$18,NA()),NA())))) -> 0 | AQ8: =(AP8-AO8)^2 -> 0 | AR8: =(AO8-$AO$104)^2 -> #N/A
F9: 7 | G9: =MIN(x1Data)+(MAX(x1Data)-MIN(x1Data))*(F9/100) -> 560 | H9: =IF($D$1=1,$C$11+$B$11*G9, IF($D$1=2,$B$11*G9^#REF!,IF($D$1=3,$D$11+$C$11*G9+$B$11*(G9)^2,IF($D$1=4,$E$11+$D$11*G9+$C$11*(G9)^2+$B$11*(G9)^3,IF($D$1=5,EXP($C$11)*G9^($B$11),IF($D$1=6,EXP($C$11+G9*$B$11), NA())))))) -> #N/A | J9: =IFERROR(MIN(DA_x1data,DA_x2data)+(MAX(DA_x1data,DA_x2data)-MIN(DA_x1data,DA_x2data))*(F9/100), MIN(DA_x1data)+(MAX(DA_x1data)-MIN(DA_x1data))*(F9/100)) -> #N/A | K9: =IF($D$32=1,$B$48*J9+$C$48,IF($D$32=2,$B$48*J9^2+$C$48*J9+$D$48,IF($D$32=3,$B$48*J9^3+$C$48*J9^2+$D$48*J9+$E$48,IF($D$32=4,$B$48*J9^'Double Analysis'!$G$13,IF($D$32=5,EXP($C$48)*J9^$B$48,IF($D$32=6,EXP($C$48+J9*$B$48),NA())))))) -> #N/A | L9: =IF($D$32=1,$B$54*J9+$C$54,IF($D$32=2,$B$54*J9^2+$C$54*J9+$D$54,IF($D$32=3,$B$54*J9^3+$C$54*J9^2+$D$54*J9+$E$54,IF($D$32=4,$B$54*J9^'Double Analysis'!$G$13,IF($D$32=5,EXP($C$54)*J9^$B$54,IF($D$32=6,EXP($C$54+J9*$B$54),NA())))))) -> #N/A | N9: =IFERROR(SMALL($R$2:$R$102, ROW()-1),NA()) -> 3000 | O9: =IF(ISNUMBER(N9),INDEX(y1Data,MATCH(N9,$R$2:$R$102,0)),NA()) -> 11.36 | P9: =IF($D$1=7,O9,NA()) -> #N/A | Q9: 7000 | R9: =IF(Q9<>"",Q9+(0.0000000000001)*(COUNTIF($Q9:Q$102,Q9)-1),"") -> 7000 | Y9: =IF(ISNUMBER(T9),T9," ") | Z9: =IFERROR(SMALL($Y$2:$Y$102,ROW()-1),NA()) -> #N/A | AA9: {=IF(ISNUMBER(Z9),INDEX(DA_y1data,MATCH(Z9,$Y$2:$Y$102,0)),NA())} -> #N/A | AB9: =IF($D$32=7,AA9,NA()) -> #N/A | AC9: =IF(ISNUMBER(V9),V9," ") | AD9: =IFERROR(SMALL($AC$2:$AC$102,ROW()-1),NA()) -> #N/A | AE9: {=IF(ISNUMBER(AD9),INDEX(DA_y2data,MATCH(AD9,$AC$2:$AC$102,0)),NA())} -> #N/A | AF9: =IF($D$32=7,AE9,NA()) -> #N/A | AK9: =MIN('Manual Fitting'!$A$3:$A$32)+(MAX('Manual Fitting'!$A$3:$A$32)-MIN('Manual Fitting'!$A$3:$A$17))*(Guts!F9/100) -> 0 | AL9: =IF($AI$1=1,IF(AND(ISNUMBER($AH$15),ISNUMBER($AH$16)),$AH$15+AK9*$AH$16,NA()),IF($AI$1=2,IF(AND(ISNUMBER($AH$15),ISNUMBER($AH$16),ISNUMBER($AH$17)),$AH$15/(1+((AK9-$AH$16)/$AH$17)^2),NA()),IF($AI$1=3,IF(AND(ISNUMBER($AH$15),ISNUMBER($AH$16),ISNUMBER($AH$17)),$AH$15*EXP((-1)*((AK9-$AH$16)/$AH$17)^2),NA()), IF($AI$1=4,IF(AND(ISNUMBER($AH$15),ISNUMBER($AH$16),ISNUMBER($AH$17),ISNUMBER($AH$18)),$AH$15*SIN((AK9*$AH$16)-$AH$17)+$AH$18,NA()),NA())))) -> 0 | AP9: =IF($AI$1=1,IF(AND(ISNUMBER($AH$15),ISNUMBER($AH$16)),$AH$15+AN9*$AH$16,NA()),IF($AI$1=2,IF(AND(ISNUMBER($AH$15),ISNUMBER($AH$16),ISNUMBER($AH$17)),$AH$15/(1+((AN9-$AH$16)/$AH$17)^2),NA()), IF($AI$1=3,IF(AND(ISNUMBER($AH$15),ISNUMBER($AH$16),ISNUMBER($AH$17)),$AH$15*EXP(-(((AN9-$AH$16)/$AH$17)^2)),NA()),IF($AI$1=4,IF(AND(ISNUMBER($AH$15),ISNUMBER($AH$16),ISNUMBER($AH$17),ISNUMBER($AH$18)),$AH$15*SIN($AH$16*AN9-$AH$17)+$AH$18,NA()),NA())))) -> 0 | AQ9: =(AP9-AO9)^2 -> 0 | AR9: =(AO9-$AO$104)^2 -> #N/A
A10: Analysis fit parameters | F10: 8 | G10: =MIN(x1Data)+(MAX(x1Data)-MIN(x1Data))*(F10/100) -> 640 | H10: =IF($D$1=1,$C$11+$B$11*G10, IF($D$1=2,$B$11*G10^#REF!,IF($D$1=3,$D$11+$C$11*G10+$B$11*(G10)^2,IF($D$1=4,$E$11+$D$11*G10+$C$11*(G10)^2+$B$11*(G10)^3,IF($D$1=5,EXP($C$11)*G10^($B$11),IF($D$1=6,EXP($C$11+G10*$B$11), NA())))))) -> #N/A | J10: =IFERROR(MIN(DA_x1data,DA_x2data)+(MAX(DA_x1data,DA_x2data)-MIN(DA_x1data,DA_x2data))*(F10/100), MIN(DA_x1data)+(MAX(DA_x1data)-MIN(DA_x1data))*(F10/100)) -> #N/A | K10: =IF($D$32=1,$B$48*J10+$C$48,IF($D$32=2,$B$48*J10^2+$C$48*J10+$D$48,IF($D$32=3,$B$48*J10^3+$C$48*J10^2+$D$48*J10+$E$48,IF($D$32=4,$B$48*J10^'Double Analysis'!$G$13,IF($D$32=5,EXP($C$48)*J10^$B$48,IF($D$32=6,EXP($C$48+J10*$B$48),NA())))))) -> #N/A | L10: =IF($D$32=1,$B$54*J10+$C$54,IF($D$32=2,$B$54*J10^2+$C$54*J10+$D$54,IF($D$32=3,$B$54*J10^3+$C$54*J10^2+$D$54*J10+$E$54,IF($D$32=4,$B$54*J10^'Double Analysis'!$G$13,IF($D$32=5,EXP($C$54)*J10^$B$54,IF($D$32=6,EXP($C$54+J10*$B$54),NA())))))) -> #N/A | N10: =IFERROR(SMALL($R$2:$R$102, ROW()-1),NA()) -> 4000 | O10: =IF(ISNUMBER(N10),INDEX(y1Data,MATCH(N10,$R$2:$R$102,0)),NA()) -> 15.08 | P10: =IF($D$1=7,O10,NA()) -> #N/A | Q10: 8000 | R10: =IF(Q10<>"",Q10+(0.0000000000001)*(COUNTIF($Q10:Q$102,Q10)-1),"") -> 8000 | Y10: =IF(ISNUMBER(T10),T10," ") | Z10: =IFERROR(SMALL($Y$2:$Y$102,ROW()-1),NA()) -> #N/A | AA10: {=IF(ISNUMBER(Z10),INDEX(DA_y1data,MATCH(Z10,$Y$2:$Y$102,0)),NA())} -> #N/A | AB10: =IF($D$32=7,AA10,NA()) -> #N/A | AC10: =IF(ISNUMBER(V10),V10," ") | AD10: =IFERROR(SMALL($AC$2:$AC$102,ROW()-1),NA()) -> #N/A | AE10: {=IF(ISNUMBER(AD10),INDEX(DA_y2data,MATCH(AD10,$AC$2:$AC$102,0)),NA())} -> #N/A | AF10: =IF($D$32=7,AE10,NA()) -> #N/A | AK10: =MIN('Manual Fitting'!$A$3:$A$32)+(MAX('Manual Fitting'!$A$3:$A$32)-MIN('Manual Fitting'!$A$3:$A$17))*(Guts!F10/100) -> 0 | AL10: =IF($AI$1=1,IF(AND(ISNUMBER($AH$15),ISNUMBER($AH$16)),$AH$15+AK10*$AH$16,NA()),IF($AI$1=2,IF(AND(ISNUMBER($AH$15),ISNUMBER($AH$16),ISNUMBER($AH$17)),$AH$15/(1+((AK10-$AH$16)/$AH$17)^2),NA()),IF($AI$1=3,IF(AND(ISNUMBER($AH$15),ISNUMBER($AH$16),ISNUMBER($AH$17)),$AH$15*EXP((-1)*((AK10-$AH$16)/$AH$17)^2),NA()), IF($AI$1=4,IF(AND(ISNUMBER($AH$15),ISNUMBER($AH$16),ISNUMBER($AH$17),ISNUMBER($AH$18)),$AH$15*SIN((AK10*$AH$16)-$AH$17)+$AH$18,NA()),NA())))) -> 0 | AP10: =IF($AI$1=1,IF(AND(ISNUMBER($AH$15),ISNUMBER($AH$16)),$AH$15+AN10*$AH$16,NA()),IF($AI$1=2,IF(AND(ISNUMBER($AH$15),ISNUMBER($AH$16),ISNUMBER($AH$17)),$AH$15/(1+((AN10-$AH$16)/$AH$17)^2),NA()), IF($AI$1=3,IF(AND(ISNUMBER($AH$15),ISNUMBER($AH$16),ISNUMBER($AH$17)),$AH$15*EXP(-(((AN10-$AH$16)/$AH$17)^2)),NA()),IF($AI$1=4,IF(AND(ISNUMBER($AH$15),ISNUMBER($AH$16),ISNUMBER($AH$17),ISNUMBER($AH$18)),$AH$15*SIN($AH$16*AN10-$AH$17)+$AH$18,NA()),NA())))) -> 0 | AQ10: =(AP10-AO10)^2 -> 0 | AR10: =(AO10-$AO$104)^2 -> #N/A
A11: coeffs | B11: {=IF(D1=1,LINEST(Guts!ytograph,Guts!xtograph,1,1),IF(D1=2,LINEST(Guts!ytograph,Guts!xtograph^#REF!,0,1),IF(D1=3, LINEST(Guts!ytograph,Guts!xtograph^{1,2},1,1),IF(D1=4,LINEST(Guts!ytograph,Guts!xtograph^{1,2,3},1,1), IF(D1=5,LINEST(LN(Guts!ytograph),LN(Guts!xtograph),1,1),IF(D1=6,LINEST(LN(Guts!ytograph),Guts!xtograph,1,1),NA()))))))} -> #N/A | F11: 9 | G11: =MIN(x1Data)+(MAX(x1Data)-MIN(x1Data))*(F11/100) -> 720 | H11: =IF($D$1=1,$C$11+$B$11*G11, IF($D$1=2,$B$11*G11^#REF!,IF($D$1=3,$D$11+$C$11*G11+$B$11*(G11)^2,IF($D$1=4,$E$11+$D$11*G11+$C$11*(G11)^2+$B$11*(G11)^3,IF($D$1=5,EXP($C$11)*G11^($B$11),IF($D$1=6,EXP($C$11+G11*$B$11), NA())))))) -> #N/A | J11: =IFERROR(MIN(DA_x1data,DA_x2data)+(MAX(DA_x1data,DA_x2data)-MIN(DA_x1data,DA_x2data))*(F11/100), MIN(DA_x1data)+(MAX(DA_x1data)-MIN(DA_x1data))*(F11/100)) -> #N/A | K11: =IF($D$32=1,$B$48*J11+$C$48,IF($D$32=2,$B$48*J11^2+$C$48*J11+$D$48,IF($D$32=3,$B$48*J11^3+$C$48*J11^2+$D$48*J11+$E$48,IF($D$32=4,$B$48*J11^'Double Analysis'!$G$13,IF($D$32=5,EXP($C$48)*J11^$B$48,IF($D$32=6,EXP($C$48+J11*$B$48),NA())))))) -> #N/A | L11: =IF($D$32=1,$B$54*J11+$C$54,IF($D$32=2,$B$54*J11^2+$C$54*J11+$D$54,IF($D$32=3,$B$54*J11^3+$C$54*J11^2+$D$54*J11+$E$54,IF($D$32=4,$B$54*J11^'Double Analysis'!$G$13,IF($D$32=5,EXP($C$54)*J11^$B$54,IF($D$32=6,EXP($C$54+J11*$B$54),NA())))))) -> #N/A | N11: =IFERROR(SMALL($R$2:$R$102, ROW()-1),NA()) -> 4000 | O11: =IF(ISNUMBER(N11),INDEX(y1Data,MATCH(N11,$R$2:$R$102,0)),NA()) -> 15.08 | P11: =IF($D$1=7,O11,NA()) -> #N/A | Q11: 7000 | R11: =IF(Q11<>"",Q11+(0.0000000000001)*(COUNTIF($Q11:Q$102,Q11)-1),"") -> 7000 | Y11: =IF(ISNUMBER(T11),T11," ") | Z11: =IFERROR(SMALL($Y$2:$Y$102,ROW()-1),NA()) -> #N/A | AA11: {=IF(ISNUMBER(Z11),INDEX(DA_y1data,MATCH(Z11,$Y$2:$Y$102,0)),NA())} -> #N/A | AB11: =IF($D$32=7,AA11,NA()) -> #N/A | AC11: =IF(ISNUMBER(V11),V11," ") | AD11: =IFERROR(SMALL($AC$2:$AC$102,ROW()-1),NA()) -> #N/A | AE11: {=IF(ISNUMBER(AD11),INDEX(DA_y2data,MATCH(AD11,$AC$2:$AC$102,0)),NA())} -> #N/A | AF11: =IF($D$32=7,AE11,NA()) -> #N/A | AH11: =EXP((-1)*((AK2-AH16)/AH17)^2) -> #N/A | AK11: =MIN('Manual Fitting'!$A$3:$A$32)+(MAX('Manual Fitting'!$A$3:$A$32)-MIN('Manual Fitting'!$A$3:$A$17))*(Guts!F11/100) -> 0 | AL11: =IF($AI$1=1,IF(AND(ISNUMBER($AH$15),ISNUMBER($AH$16)),$AH$15+AK11*$AH$16,NA()),IF($AI$1=2,IF(AND(ISNUMBER($AH$15),ISNUMBER($AH$16),ISNUMBER($AH$17)),$AH$15/(1+((AK11-$AH$16)/$AH$17)^2),NA()),IF($AI$1=3,IF(AND(ISNUMBER($AH$15),ISNUMBER($AH$16),ISNUMBER($AH$17)),$AH$15*EXP((-1)*((AK11-$AH$16)/$AH$17)^2),NA()), IF($AI$1=4,IF(AND(ISNUMBER($AH$15),ISNUMBER($AH$16),ISNUMBER($AH$17),ISNUMBER($AH$18)),$AH$15*SIN((AK11*$AH$16)-$AH$17)+$AH$18,NA()),NA())))) -> 0 | AP11: =IF($AI$1=1,IF(AND(ISNUMBER($AH$15),ISNUMBER($AH$16)),$AH$15+AN11*$AH$16,NA()),IF($AI$1=2,IF(AND(ISNUMBER($AH$15),ISNUMBER($AH$16),ISNUMBER($AH$17)),$AH$15/(1+((AN11-$AH$16)/$AH$17)^2),NA()), IF($AI$1=3,IF(AND(ISNUMBER($AH$15),ISNUMBER($AH$16),ISNUMBER($AH$17)),$AH$15*EXP(-(((AN11-$AH$16)/$AH$17)^2)),NA()),IF($AI$1=4,IF(AND(ISNUMBER($AH$15),ISNUMBER($AH$16),ISNUMBER($AH$17),ISNUMBER($AH$18)),$AH$15*SIN($AH$16*AN11-$AH$17)+$AH$18,NA()),NA())))) -> 0 | AQ11: =(AP11-AO11)^2 -> 0 | AR11: =(AO11-$AO$104)^2 -> #N/A
A12: unc. | F12: 10 | G12: =MIN(x1Data)+(MAX(x1Data)-MIN(x1Data))*(F12/100) -> 800 | H12: =IF($D$1=1,$C$11+$B$11*G12, IF($D$1=2,$B$11*G12^#REF!,IF($D$1=3,$D$11+$C$11*G12+$B$11*(G12)^2,IF($D$1=4,$E$11+$D$11*G12+$C$11*(G12)^2+$B$11*(G12)^3,IF($D$1=5,EXP($C$11)*G12^($B$11),IF($D$1=6,EXP($C$11+G12*$B$11), NA())))))) -> #N/A | J12: =IFERROR(MIN(DA_x1data,DA_x2data)+(MAX(DA_x1data,DA_x2data)-MIN(DA_x1data,DA_x2data))*(F12/100), MIN(DA_x1data)+(MAX(DA_x1data)-MIN(DA_x1data))*(F12/100)) -> #N/A | K12: =IF($D$32=1,$B$48*J12+$C$48,IF($D$32=2,$B$48*J12^2+$C$48*J12+$D$48,IF($D$32=3,$B$48*J12^3+$C$48*J12^2+$D$48*J12+$E$48,IF($D$32=4,$B$48*J12^'Double Analysis'!$G$13,IF($D$32=5,EXP($C$48)*J12^$B$48,IF($D$32=6,EXP($C$48+J12*$B$48),NA())))))) -> #N/A | L12: =IF($D$32=1,$B$54*J12+$C$54,IF($D$32=2,$B$54*J12^2+$C$54*J12+$D$54,IF($D$32=3,$B$54*J12^3+$C$54*J12^2+$D$54*J12+$E$54,IF($D$32=4,$B$54*J12^'Double Analysis'!$G$13,IF($D$32=5,EXP($C$54)*J12^$B$54,IF($D$32=6,EXP($C$54+J12*$B$54),NA())))))) -> #N/A | N12: =IFERROR(SMALL($R$2:$R$102, ROW()-1),NA()) -> 5000 | O12: =IF(ISNUMBER(N12),INDEX(y1Data,MATCH(N12,$R$2:$R$102,0)),NA()) -> 18.72 | P12: =IF($D$1=7,O12,NA()) -> #N/A | Q12: 6000 | R12: =IF(Q12<>"",Q12+(0.0000000000001)*(COUNTIF($Q12:Q$102,Q12)-1),"") -> 6000 | Y12: =IF(ISNUMBER(T12),T12," ") | Z12: =IFERROR(SMALL($Y$2:$Y$102,ROW()-1),NA()) -> #N/A | AA12: {=IF(ISNUMBER(Z12),INDEX(DA_y1data,MATCH(Z12,$Y$2:$Y$102,0)),NA())} -> #N/A | AB12: =IF($D$32=7,AA12,NA()) -> #N/A | AC12: =IF(ISNUMBER(V12),V12," ") | AD12: =IFERROR(SMALL($AC$2:$AC$102,ROW()-1),NA()) -> #N/A | AE12: {=IF(ISNUMBER(AD12),INDEX(DA_y2data,MATCH(AD12,$AC$2:$AC$102,0)),NA())} -> #N/A | AF12: =IF($D$32=7,AE12,NA()) -> #N/A | AK12: =MIN('Manual Fitting'!$A$3:$A$32)+(MAX('Manual Fitting'!$A$3:$A$32)-MIN('Manual Fitting'!$A$3:$A$17))*(Guts!F12/100) -> 0 | AL12: =IF($AI$1=1,IF(AND(ISNUMBER($AH$15),ISNUMBER($AH$16)),$AH$15+AK12*$AH$16,NA()),IF($AI$1=2,IF(AND(ISNUMBER($AH$15),ISNUMBER($AH$16),ISNUMBER($AH$17)),$AH$15/(1+((AK12-$AH$16)/$AH$17)^2),NA()),IF($AI$1=3,IF(AND(ISNUMBER($AH$15),ISNUMBER($AH$16),ISNUMBER($AH$17)),$AH$15*EXP((-1)*((AK12-$AH$16)/$AH$17)^2),NA()), IF($AI$1=4,IF(AND(ISNUMBER($AH$15),ISNUMBER($AH$16),ISNUMBER($AH$17),ISNUMBER($AH$18)),$AH$15*SIN((AK12*$AH$16)-$AH$17)+$AH$18,NA()),NA())))) -> 0 | AP12: =IF($AI$1=1,IF(AND(ISNUMBER($AH$15),ISNUMBER($AH$16)),$AH$15+AN12*$AH$16,NA()),IF($AI$1=2,IF(AND(ISNUMBER($AH$15),ISNUMBER($AH$16),ISNUMBER($AH$17)),$AH$15/(1+((AN12-$AH$16)/$AH$17)^2),NA()), IF($AI$1=3,IF(AND(ISNUMBER($AH$15),ISNUMBER($AH$16),ISNUMBER($AH$17)),$AH$15*EXP(-(((AN12-$AH$16)/$AH$17)^2)),NA()),IF($AI$1=4,IF(AND(ISNUMBER($AH$15),ISNUMBER($AH$16),ISNUMBER($AH$17),ISNUMBER($AH$18)),$AH$15*SIN($AH$16*AN12-$AH$17)+$AH$18,NA()),NA())))) -> 0 | AQ12: =(AP12-AO12)^2 -> 0 | AR12: =(AO12-$AO$104)^2 -> #N/A
A13: stats | F13: 11 | G13: =MIN(x1Data)+(MAX(x1Data)-MIN(x1Data))*(F13/100) -> 880 | H13: =IF($D$1=1,$C$11+$B$11*G13, IF($D$1=2,$B$11*G13^#REF!,IF($D$1=3,$D$11+$C$11*G13+$B$11*(G13)^2,IF($D$1=4,$E$11+$D$11*G13+$C$11*(G13)^2+$B$11*(G13)^3,IF($D$1=5,EXP($C$11)*G13^($B$11),IF($D$1=6,EXP($C$11+G13*$B$11), NA())))))) -> #N/A | J13: =IFERROR(MIN(DA_x1data,DA_x2data)+(MAX(DA_x1data,DA_x2data)-MIN(DA_x1data,DA_x2data))*(F13/100), MIN(DA_x1data)+(MAX(DA_x1data)-MIN(DA_x1data))*(F13/100)) -> #N/A | K13: =IF($D$32=1,$B$48*J13+$C$48,IF($D$32=2,$B$48*J13^2+$C$48*J13+$D$48,IF($D$32=3,$B$48*J13^3+$C$48*J13^2+$D$48*J13+$E$48,IF($D$32=4,$B$48*J13^'Double Analysis'!$G$13,IF($D$32=5,EXP($C$48)*J13^$B$48,IF($D$32=6,EXP($C$48+J13*$B$48),NA())))))) -> #N/A | L13: =IF($D$32=1,$B$54*J13+$C$54,IF($D$32=2,$B$54*J13^2+$C$54*J13+$D$54,IF($D$32=3,$B$54*J13^3+$C$54*J13^2+$D$54*J13+$E$54,IF($D$32=4,$B$54*J13^'Double Analysis'!$G$13,IF($D$32=5,EXP($C$54)*J13^$B$54,IF($D$32=6,EXP($C$54+J13*$B$54),NA())))))) -> #N/A | N13: =IFERROR(SMALL($R$2:$R$102, ROW()-1),NA()) -> 5000 | O13: =IF(ISNUMBER(N13),INDEX(y1Data,MATCH(N13,$R$2:$R$102,0)),NA()) -> 18.72 | P13: =IF($D$1=7,O13,NA()) -> #N/A | Q13: 5000 | R13: =IF(Q13<>"",Q13+(0.0000000000001)*(COUNTIF($Q13:Q$102,Q13)-1),"") -> 5000 | Y13: =IF(ISNUMBER(T13),T13," ") | Z13: =IFERROR(SMALL($Y$2:$Y$102,ROW()-1),NA()) -> #N/A | AA13: {=IF(ISNUMBER(Z13),INDEX(DA_y1data,MATCH(Z13,$Y$2:$Y$102,0)),NA())} -> #N/A | AB13: =IF($D$32=7,AA13,NA()) -> #N/A | AC13: =IF(ISNUMBER(V13),V13," ") | AD13: =IFERROR(SMALL($AC$2:$AC$102,ROW()-1),NA()) -> #N/A | AE13: {=IF(ISNUMBER(AD13),INDEX(DA_y2data,MATCH(AD13,$AC$2:$AC$102,0)),NA())} -> #N/A | AF13: =IF($D$32=7,AE13,NA()) -> #N/A | AK13: =MIN('Manual Fitting'!$A$3:$A$32)+(MAX('Manual Fitting'!$A$3:$A$32)-MIN('Manual Fitting'!$A$3:$A$17))*(Guts!F13/100) -> 0 | AL13: =IF($AI$1=1,IF(AND(ISNUMBER($AH$15),ISNUMBER($AH$16)),$AH$15+AK13*$AH$16,NA()),IF($AI$1=2,IF(AND(ISNUMBER($AH$15),ISNUMBER($AH$16),ISNUMBER($AH$17)),$AH$15/(1+((AK13-$AH$16)/$AH$17)^2),NA()),IF($AI$1=3,IF(AND(ISNUMBER($AH$15),ISNUMBER($AH$16),ISNUMBER($AH$17)),$AH$15*EXP((-1)*((AK13-$AH$16)/$AH$17)^2),NA()), IF($AI$1=4,IF(AND(ISNUMBER($AH$15),ISNUMBER($AH$16),ISNUMBER($AH$17),ISNUMBER($AH$18)),$AH$15*SIN((AK13*$AH$16)-$AH$17)+$AH$18,NA()),NA())))) -> 0 | AP13: =IF($AI$1=1,IF(AND(ISNUMBER($AH$15),ISNUMBER($AH$16)),$AH$15+AN13*$AH$16,NA()),IF($AI$1=2,IF(AND(ISNUMBER($AH$15),ISNUMBER($AH$16),ISNUMBER($AH$17)),$AH$15/(1+((AN13-$AH$16)/$AH$17)^2),NA()), IF($AI$1=3,IF(AND(ISNUMBER($AH$15),ISNUMBER($AH$16),ISNUMBER($AH$17)),$AH$15*EXP(-(((AN13-$AH$16)/$AH$17)^2)),NA()),IF($AI$1=4,IF(AND(ISNUMBER($AH$15),ISNUMBER($AH$16),ISNUMBER($AH$17),ISNUMBER($AH$18)),$AH$15*SIN($AH$16*AN13-$AH$17)+$AH$18,NA()),NA())))) -> 0 | AQ13: =(AP13-AO13)^2 -> 0 | AR13: =(AO13-$AO$104)^2 -> #N/A
F14: 12 | G14: =MIN(x1Data)+(MAX(x1Data)-MIN(x1Data))*(F14/100) -> 960 | H14: =IF($D$1=1,$C$11+$B$11*G14, IF($D$1=2,$B$11*G14^#REF!,IF($D$1=3,$D$11+$C$11*G14+$B$11*(G14)^2,IF($D$1=4,$E$11+$D$11*G14+$C$11*(G14)^2+$B$11*(G14)^3,IF($D$1=5,EXP($C$11)*G14^($B$11),IF($D$1=6,EXP($C$11+G14*$B$11), NA())))))) -> #N/A | J14: =IFERROR(MIN(DA_x1data,DA_x2data)+(MAX(DA_x1data,DA_x2data)-MIN(DA_x1data,DA_x2data))*(F14/100), MIN(DA_x1data)+(MAX(DA_x1data)-MIN(DA_x1data))*(F14/100)) -> #N/A | K14: =IF($D$32=1,$B$48*J14+$C$48,IF($D$32=2,$B$48*J14^2+$C$48*J14+$D$48,IF($D$32=3,$B$48*J14^3+$C$48*J14^2+$D$48*J14+$E$48,IF($D$32=4,$B$48*J14^'Double Analysis'!$G$13,IF($D$32=5,EXP($C$48)*J14^$B$48,IF($D$32=6,EXP($C$48+J14*$B$48),NA())))))) -> #N/A | L14: =IF($D$32=1,$B$54*J14+$C$54,IF($D$32=2,$B$54*J14^2+$C$54*J14+$D$54,IF($D$32=3,$B$54*J14^3+$C$54*J14^2+$D$54*J14+$E$54,IF($D$32=4,$B$54*J14^'Double Analysis'!$G$13,IF($D$32=5,EXP($C$54)*J14^$B$54,IF($D$32=6,EXP($C$54+J14*$B$54),NA())))))) -> #N/A | N14: =IFERROR(SMALL($R$2:$R$102, ROW()-1),NA()) -> 6000 | O14: =IF(ISNUMBER(N14),INDEX(y1Data,MATCH(N14,$R$2:$R$102,0)),NA()) -> 22.36 | P14: =IF($D$1=7,O14,NA()) -> #N/A | Q14: 4000 | R14: =IF(Q14<>"",Q14+(0.0000000000001)*(COUNTIF($Q14:Q$102,Q14)-1),"") -> 4000 | Y14: =IF(ISNUMBER(T14),T14," ") | Z14: =IFERROR(SMALL($Y$2:$Y$102,ROW()-1),NA()) -> #N/A | AA14: {=IF(ISNUMBER(Z14),INDEX(DA_y1data,MATCH(Z14,$Y$2:$Y$102,0)),NA())} -> #N/A | AB14: =IF($D$32=7,AA14,NA()) -> #N/A | AC14: =IF(ISNUMBER(V14),V14," ") | AD14: =IFERROR(SMALL($AC$2:$AC$102,ROW()-1),NA()) -> #N/A | AE14: {=IF(ISNUMBER(AD14),INDEX(DA_y2data,MATCH(AD14,$AC$2:$AC$102,0)),NA())} -> #N/A | AF14: =IF($D$32=7,AE14,NA()) -> #N/A | AH14: guessed | AI14: solved | AK14: =MIN('Manual Fitting'!$A$3:$A$32)+(MAX('Manual Fitting'!$A$3:$A$32)-MIN('Manual Fitting'!$A$3:$A$17))*(Guts!F14/100) -> 0 | AL14: =IF($AI$1=1,IF(AND(ISNUMBER($AH$15),ISNUMBER($AH$16)),$AH$15+AK14*$AH$16,NA()),IF($AI$1=2,IF(AND(ISNUMBER($AH$15),ISNUMBER($AH$16),ISNUMBER($AH$17)),$AH$15/(1+((AK14-$AH$16)/$AH$17)^2),NA()),IF($AI$1=3,IF(AND(ISNUMBER($AH$15),ISNUMBER($AH$16),ISNUMBER($AH$17)),$AH$15*EXP((-1)*((AK14-$AH$16)/$AH$17)^2),NA()), IF($AI$1=4,IF(AND(ISNUMBER($AH$15),ISNUMBER($AH$16),ISNUMBER($AH$17),ISNUMBER($AH$18)),$AH$15*SIN((AK14*$AH$16)-$AH$17)+$AH$18,NA()),NA())))) -> 0 | AP14: =IF($AI$1=1,IF(AND(ISNUMBER($AH$15),ISNUMBER($AH$16)),$AH$15+AN14*$AH$16,NA()),IF($AI$1=2,IF(AND(ISNUMBER($AH$15),ISNUMBER($AH$16),ISNUMBER($AH$17)),$AH$15/(1+((AN14-$AH$16)/$AH$17)^2),NA()), IF($AI$1=3,IF(AND(ISNUMBER($AH$15),ISNUMBER($AH$16),ISNUMBER($AH$17)),$AH$15*EXP(-(((AN14-$AH$16)/$AH$17)^2)),NA()),IF($AI$1=4,IF(AND(ISNUMBER($AH$15),ISNUMBER($AH$16),ISNUMBER($AH$17),ISNUMBER($AH$18)),$AH$15*SIN($AH$16*AN14-$AH$17)+$AH$18,NA()),NA())))) -> 0 | AQ14: =(AP14-AO14)^2 -> 0 | AR14: =(AO14-$AO$104)^2 -> #N/A
F15: 13 | G15: =MIN(x1Data)+(MAX(x1Data)-MIN(x1Data))*(F15/100) -> 1040 | H15: =IF($D$1=1,$C$11+$B$11*G15, IF($D$1=2,$B$11*G15^#REF!,IF($D$1=3,$D$11+$C$11*G15+$B$11*(G15)^2,IF($D$1=4,$E$11+$D$11*G15+$C$11*(G15)^2+$B$11*(G15)^3,IF($D$1=5,EXP($C$11)*G15^($B$11),IF($D$1=6,EXP($C$11+G15*$B$11), NA())))))) -> #N/A | J15: =IFERROR(MIN(DA_x1data,DA_x2data)+(MAX(DA_x1data,DA_x2data)-MIN(DA_x1data,DA_x2data))*(F15/100), MIN(DA_x1data)+(MAX(DA_x1data)-MIN(DA_x1data))*(F15/100)) -> #N/A | K15: =IF($D$32=1,$B$48*J15+$C$48,IF($D$32=2,$B$48*J15^2+$C$48*J15+$D$48,IF($D$32=3,$B$48*J15^3+$C$48*J15^2+$D$48*J15+$E$48,IF($D$32=4,$B$48*J15^'Double Analysis'!$G$13,IF($D$32=5,EXP($C$48)*J15^$B$48,IF($D$32=6,EXP($C$48+J15*$B$48),NA())))))) -> #N/A | L15: =IF($D$32=1,$B$54*J15+$C$54,IF($D$32=2,$B$54*J15^2+$C$54*J15+$D$54,IF($D$32=3,$B$54*J15^3+$C$54*J15^2+$D$54*J15+$E$54,IF($D$32=4,$B$54*J15^'Double Analysis'!$G$13,IF($D$32=5,EXP($C$54)*J15^$B$54,IF($D$32=6,EXP($C$54+J15*$B$54),NA())))))) -> #N/A | N15: =IFERROR(SMALL($R$2:$R$102, ROW()-1),NA()) -> 6000 | O15: =IF(ISNUMBER(N15),INDEX(y1Data,MATCH(N15,$R$2:$R$102,0)),NA()) -> 22.36 | P15: =IF($D$1=7,O15,NA()) -> #N/A | Q15: 3000 | R15: =IF(Q15<>"",Q15+(0.0000000000001)*(COUNTIF($Q15:Q$102,Q15)-1),"") -> 3000 | Y15: =IF(ISNUMBER(T15),T15," ") | Z15: =IFERROR(SMALL($Y$2:$Y$102,ROW()-1),NA()) -> #N/A | AA15: {=IF(ISNUMBER(Z15),INDEX(DA_y1data,MATCH(Z15,$Y$2:$Y$102,0)),NA())} -> #N/A | AB15: =IF($D$32=7,AA15,NA()) -> #N/A | AC15: =IF(ISNUMBER(V15),V15," ") | AD15: =IFERROR(SMALL($AC$2:$AC$102,ROW()-1),NA()) -> #N/A | AE15: {=IF(ISNUMBER(AD15),INDEX(DA_y2data,MATCH(AD15,$AC$2:$AC$102,0)),NA())} -> #N/A | AF15: =IF($D$32=7,AE15,NA()) -> #N/A | AH15: =IF(ISNUMBER('Manual Fitting'!H28),'Manual Fitting'!H28,NA()) -> 0 | AI15: 6264.7982 | AK15: =MIN('Manual Fitting'!$A$3:$A$32)+(MAX('Manual Fitting'!$A$3:$A$32)-MIN('Manual Fitting'!$A$3:$A$17))*(Guts!F15/100) -> 0 | AL15: =IF($AI$1=1,IF(AND(ISNUMBER($AH$15),ISNUMBER($AH$16)),$AH$15+AK15*$AH$16,NA()),IF($AI$1=2,IF(AND(ISNUMBER($AH$15),ISNUMBER($AH$16),ISNUMBER($AH$17)),$AH$15/(1+((AK15-$AH$16)/$AH$17)^2),NA()),IF($AI$1=3,IF(AND(ISNUMBER($AH$15),ISNUMBER($AH$16),ISNUMBER($AH$17)),$AH$15*EXP((-1)*((AK15-$AH$16)/$AH$17)^2),NA()), IF($AI$1=4,IF(AND(ISNUMBER($AH$15),ISNUMBER($AH$16),ISNUMBER($AH$17),ISNUMBER($AH$18)),$AH$15*SIN((AK15*$AH$16)-$AH$17)+$AH$18,NA()),NA())))) -> 0 | AP15: =IF($AI$1=1,IF(AND(ISNUMBER($AH$15),ISNUMBER($AH$16)),$AH$15+AN15*$AH$16,NA()),IF($AI$1=2,IF(AND(ISNUMBER($AH$15),ISNUMBER($AH$16),ISNUMBER($AH$17)),$AH$15/(1+((AN15-$AH$16)/$AH$17)^2),NA()), IF($AI$1=3,IF(AND(ISNUMBER($AH$15),ISNUMBER($AH$16),ISNUMBER($AH$17)),$AH$15*EXP(-(((AN15-$AH$16)/$AH$17)^2)),NA()),IF($AI$1=4,IF(AND(ISNUMBER($AH$15),ISNUMBER($AH$16),ISNUMBER($AH$17),ISNUMBER($AH$18)),$AH$15*SIN($AH$16*AN15-$AH$17)+$AH$18,NA()),NA())))) -> 0 | AQ15: =(AP15-AO15)^2 -> 0 | AR15: =(AO15-$AO$104)^2 -> #N/A
F16: 14 | G16: =MIN(x1Data)+(MAX(x1Data)-MIN(x1Data))*(F16/100) -> 1120 | H16: =IF($D$1=1,$C$11+$B$11*G16, IF($D$1=2,$B$11*G16^#REF!,IF($D$1=3,$D$11+$C$11*G16+$B$11*(G16)^2,IF($D$1=4,$E$11+$D$11*G16+$C$11*(G16)^2+$B$11*(G16)^3,IF($D$1=5,EXP($C$11)*G16^($B$11),IF($D$1=6,EXP($C$11+G16*$B$11), NA())))))) -> #N/A | J16: =IFERROR(MIN(DA_x1data,DA_x2data)+(MAX(DA_x1data,DA_x2data)-MIN(DA_x1data,DA_x2data))*(F16/100), MIN(DA_x1data)+(MAX(DA_x1data)-MIN(DA_x1data))*(F16/100)) -> #N/A | K16: =IF($D$32=1,$B$48*J16+$C$48,IF($D$32=2,$B$48*J16^2+$C$48*J16+$D$48,IF($D$32=3,$B$48*J16^3+$C$48*J16^2+$D$48*J16+$E$48,IF($D$32=4,$B$48*J16^'Double Analysis'!$G$13,IF($D$32=5,EXP($C$48)*J16^$B$48,IF($D$32=6,EXP($C$48+J16*$B$48),NA())))))) -> #N/A | L16: =IF($D$32=1,$B$54*J16+$C$54,IF($D$32=2,$B$54*J16^2+$C$54*J16+$D$54,IF($D$32=3,$B$54*J16^3+$C$54*J16^2+$D$54*J16+$E$54,IF($D$32=4,$B$54*J16^'Double Analysis'!$G$13,IF($D$32=5,EXP($C$54)*J16^$B$54,IF($D$32=6,EXP($C$54+J16*$B$54),NA())))))) -> #N/A | N16: =IFERROR(SMALL($R$2:$R$102, ROW()-1),NA()) -> 7000 | O16: =IF(ISNUMBER(N16),INDEX(y1Data,MATCH(N16,$R$2:$R$102,0)),NA()) -> 26.12 | P16: =IF($D$1=7,O16,NA()) -> #N/A | Q16: 2000 | R16: =IF(Q16<>"",Q16+(0.0000000000001)*(COUNTIF($Q16:Q$102,Q16)-1),"") -> 2000 | Y16: =IF(ISNUMBER(T16),T16," ") | Z16: =IFERROR(SMALL($Y$2:$Y$102,ROW()-1),NA()) -> #N/A | AA16: {=IF(ISNUMBER(Z16),INDEX(DA_y1data,MATCH(Z16,$Y$2:$Y$102,0)),NA())} -> #N/A | AB16: =IF($D$32=7,AA16,NA()) -> #N/A | AC16: =IF(ISNUMBER(V16),V16," ") | AD16: =IFERROR(SMALL($AC$2:$AC$102,ROW()-1),NA()) -> #N/A | AE16: {=IF(ISNUMBER(AD16),INDEX(DA_y2data,MATCH(AD16,$AC$2:$AC$102,0)),NA())} -> #N/A | AF16: =IF($D$32=7,AE16,NA()) -> #N/A | AH16: =IF(ISNUMBER('Manual Fitting'!H29),'Manual Fitting'!H29,NA()) -> 0.04 | AI16: 10.465919 | AK16: =MIN('Manual Fitting'!$A$3:$A$32)+(MAX('Manual Fitting'!$A$3:$A$32)-MIN('Manual Fitting'!$A$3:$A$17))*(Guts!F16/100) -> 0 | AL16: =IF($AI$1=1,IF(AND(ISNUMBER($AH$15),ISNUMBER($AH$16)),$AH$15+AK16*$AH$16,NA()),IF($AI$1=2,IF(AND(ISNUMBER($AH$15),ISNUMBER($AH$16),ISNUMBER($AH$17)),$AH$15/(1+((AK16-$AH$16)/$AH$17)^2),NA()),IF($AI$1=3,IF(AND(ISNUMBER($AH$15),ISNUMBER($AH$16),ISNUMBER($AH$17)),$AH$15*EXP((-1)*((AK16-$AH$16)/$AH$17)^2),NA()), IF($AI$1=4,IF(AND(ISNUMBER($AH$15),ISNUMBER($AH$16),ISNUMBER($AH$17),ISNUMBER($AH$18)),$AH$15*SIN((AK16*$AH$16)-$AH$17)+$AH$18,NA()),NA())))) -> 0 | AP16: =IF($AI$1=1,IF(AND(ISNUMBER($AH$15),ISNUMBER($AH$16)),$AH$15+AN16*$AH$16,NA()),IF($AI$1=2,IF(AND(ISNUMBER($AH$15),ISNUMBER($AH$16),ISNUMBER($AH$17)),$AH$15/(1+((AN16-$AH$16)/$AH$17)^2),NA()), IF($AI$1=3,IF(AND(ISNUMBER($AH$15),ISNUMBER($AH$16),ISNUMBER($AH$17)),$AH$15*EXP(-(((AN16-$AH$16)/$AH$17)^2)),NA()),IF($AI$1=4,IF(AND(ISNUMBER($AH$15),ISNUMBER($AH$16),ISNUMBER($AH$17),ISNUMBER($AH$18)),$AH$15*SIN($AH$16*AN16-$AH$17)+$AH$18,NA()),NA())))) -> 0 | AQ16: =(AP16-AO16)^2 -> 0 | AR16: =(AO16-$AO$104)^2 -> #N/A
F17: 15 | G17: =MIN(x1Data)+(MAX(x1Data)-MIN(x1Data))*(F17/100) -> 1200 | H17: =IF($D$1=1,$C$11+$B$11*G17, IF($D$1=2,$B$11*G17^#REF!,IF($D$1=3,$D$11+$C$11*G17+$B$11*(G17)^2,IF($D$1=4,$E$11+$D$11*G17+$C$11*(G17)^2+$B$11*(G17)^3,IF($D$1=5,EXP($C$11)*G17^($B$11),IF($D$1=6,EXP($C$11+G17*$B$11), NA())))))) -> #N/A | J17: =IFERROR(MIN(DA_x1data,DA_x2data)+(MAX(DA_x1data,DA_x2data)-MIN(DA_x1data,DA_x2data))*(F17/100), MIN(DA_x1data)+(MAX(DA_x1data)-MIN(DA_x1data))*(F17/100)) -> #N/A | K17: =IF($D$32=1,$B$48*J17+$C$48,IF($D$32=2,$B$48*J17^2+$C$48*J17+$D$48,IF($D$32=3,$B$48*J17^3+$C$48*J17^2+$D$48*J17+$E$48,IF($D$32=4,$B$48*J17^'Double Analysis'!$G$13,IF($D$32=5,EXP($C$48)*J17^$B$48,IF($D$32=6,EXP($C$48+J17*$B$48),NA())))))) -> #N/A | L17: =IF($D$32=1,$B$54*J17+$C$54,IF($D$32=2,$B$54*J17^2+$C$54*J17+$D$54,IF($D$32=3,$B$54*J17^3+$C$54*J17^2+$D$54*J17+$E$54,IF($D$32=4,$B$54*J17^'Double Analysis'!$G$13,IF($D$32=5,EXP($C$54)*J17^$B$54,IF($D$32=6,EXP($C$54+J17*$B$54),NA())))))) -> #N/A | N17: =IFERROR(SMALL($R$2:$R$102, ROW()-1),NA()) -> 7000 | O17: =IF(ISNUMBER(N17),INDEX(y1Data,MATCH(N17,$R$2:$R$102,0)),NA()) -> 26.12 | P17: =IF($D$1=7,O17,NA()) -> #N/A | Q17: 1000 | R17: =IF(Q17<>"",Q17+(0.0000000000001)*(COUNTIF($Q17:Q$102,Q17)-1),"") -> 1000 | Y17: =IF(ISNUMBER(T17),T17," ") | Z17: =IFERROR(SMALL($Y$2:$Y$102,ROW()-1),NA()) -> #N/A | AA17: {=IF(ISNUMBER(Z17),INDEX(DA_y1data,MATCH(Z17,$Y$2:$Y$102,0)),NA())} -> #N/A | AB17: =IF($D$32=7,AA17,NA()) -> #N/A | AC17: =IF(ISNUMBER(V17),V17," ") | AD17: =IFERROR(SMALL($AC$2:$AC$102,ROW()-1),NA()) -> #N/A | AE17: {=IF(ISNUMBER(AD17),INDEX(DA_y2data,MATCH(AD17,$AC$2:$AC$102,0)),NA())} -> #N/A | AF17: =IF($D$32=7,AE17,NA()) -> #N/A | AH17: =IF(ISNUMBER('Manual Fitting'!H30),'Manual Fitting'!H30,NA()) -> #N/A | AI17: 0.38202464 | AK17: =MIN('Manual Fitting'!$A$3:$A$32)+(MAX('Manual Fitting'!$A$3:$A$32)-MIN('Manual Fitting'!$A$3:$A$17))*(Guts!F17/100) -> 0 | AL17: =IF($AI$1=1,IF(AND(ISNUMBER($AH$15),ISNUMBER($AH$16)),$AH$15+AK17*$AH$16,NA()),IF($AI$1=2,IF(AND(ISNUMBER($AH$15),ISNUMBER($AH$16),ISNUMBER($AH$17)),$AH$15/(1+((AK17-$AH$16)/$AH$17)^2),NA()),IF($AI$1=3,IF(AND(ISNUMBER($AH$15),ISNUMBER($AH$16),ISNUMBER($AH$17)),$AH$15*EXP((-1)*((AK17-$AH$16)/$AH$17)^2),NA()), IF($AI$1=4,IF(AND(ISNUMBER($AH$15),ISNUMBER($AH$16),ISNUMBER($AH$17),ISNUMBER($AH$18)),$AH$15*SIN((AK17*$AH$16)-$AH$17)+$AH$18,NA()),NA())))) -> 0 | AP17: =IF($AI$1=1,IF(AND(ISNUMBER($AH$15),ISNUMBER($AH$16)),$AH$15+AN17*$AH$16,NA()),IF($AI$1=2,IF(AND(ISNUMBER($AH$15),ISNUMBER($AH$16),ISNUMBER($AH$17)),$AH$15/(1+((AN17-$AH$16)/$AH$17)^2),NA()), IF($AI$1=3,IF(AND(ISNUMBER($AH$15),ISNUMBER($AH$16),ISNUMBER($AH$17)),$AH$15*EXP(-(((AN17-$AH$16)/$AH$17)^2)),NA()),IF($AI$1=4,IF(AND(ISNUMBER($AH$15),ISNUMBER($AH$16),ISNUMBER($AH$17),ISNUMBER($AH$18)),$AH$15*SIN($AH$16*AN17-$AH$17)+$AH$18,NA()),NA())))) -> 0 | AQ17: =(AP17-AO17)^2 -> 0 | AR17: =(AO17-$AO$104)^2 -> #N/A
F18: 16 | G18: =MIN(x1Data)+(MAX(x1Data)-MIN(x1Data))*(F18/100) -> 1280 | H18: =IF($D$1=1,$C$11+$B$11*G18, IF($D$1=2,$B$11*G18^#REF!,IF($D$1=3,$D$11+$C$11*G18+$B$11*(G18)^2,IF($D$1=4,$E$11+$D$11*G18+$C$11*(G18)^2+$B$11*(G18)^3,IF($D$1=5,EXP($C$11)*G18^($B$11),IF($D$1=6,EXP($C$11+G18*$B$11), NA())))))) -> #N/A | J18: =IFERROR(MIN(DA_x1data,DA_x2data)+(MAX(DA_x1data,DA_x2data)-MIN(DA_x1data,DA_x2data))*(F18/100), MIN(DA_x1data)+(MAX(DA_x1data)-MIN(DA_x1data))*(F18/100)) -> #N/A | K18: =IF($D$32=1,$B$48*J18+$C$48,IF($D$32=2,$B$48*J18^2+$C$48*J18+$D$48,IF($D$32=3,$B$48*J18^3+$C$48*J18^2+$D$48*J18+$E$48,IF($D$32=4,$B$48*J18^'Double Analysis'!$G$13,IF($D$32=5,EXP($C$48)*J18^$B$48,IF($D$32=6,EXP($C$48+J18*$B$48),NA())))))) -> #N/A | L18: =IF($D$32=1,$B$54*J18+$C$54,IF($D$32=2,$B$54*J18^2+$C$54*J18+$D$54,IF($D$32=3,$B$54*J18^3+$C$54*J18^2+$D$54*J18+$E$54,IF($D$32=4,$B$54*J18^'Double Analysis'!$G$13,IF($D$32=5,EXP($C$54)*J18^$B$54,IF($D$32=6,EXP($C$54+J18*$B$54),NA())))))) -> #N/A | N18: =IFERROR(SMALL($R$2:$R$102, ROW()-1),NA()) -> 8000 | O18: =IF(ISNUMBER(N18),INDEX(y1Data,MATCH(N18,$R$2:$R$102,0)),NA()) -> 30.01 | P18: =IF($D$1=7,O18,NA()) -> #N/A | Q18: 0 | R18: =IF(Q18<>"",Q18+(0.0000000000001)*(COUNTIF($Q18:Q$102,Q18)-1),"") -> 0 | Y18: =IF(ISNUMBER(T18),T18," ") | Z18: =IFERROR(SMALL($Y$2:$Y$102,ROW()-1),NA()) -> #N/A | AA18: {=IF(ISNUMBER(Z18),INDEX(DA_y1data,MATCH(Z18,$Y$2:$Y$102,0)),NA())} -> #N/A | AB18: =IF($D$32=7,AA18,NA()) -> #N/A | AC18: =IF(ISNUMBER(V18),V18," ") | AD18: =IFERROR(SMALL($AC$2:$AC$102,ROW()-1),NA()) -> #N/A | AE18: {=IF(ISNUMBER(AD18),INDEX(DA_y2data,MATCH(AD18,$AC$2:$AC$102,0)),NA())} -> #N/A | AF18: =IF($D$32=7,AE18,NA()) -> #N/A | AH18: =IF(ISNUMBER('Manual Fitting'!H31),'Manual Fitting'!H31,NA()) -> #N/A | AI18: =AH18 -> #N/A | AK18: =MIN('Manual Fitting'!$A$3:$A$32)+(MAX('Manual Fitting'!$A$3:$A$32)-MIN('Manual Fitting'!$A$3:$A$17))*(Guts!F18/100) -> 0 | AL18: =IF($AI$1=1,IF(AND(ISNUMBER($AH$15),ISNUMBER($AH$16)),$AH$15+AK18*$AH$16,NA()),IF($AI$1=2,IF(AND(ISNUMBER($AH$15),ISNUMBER($AH$16),ISNUMBER($AH$17)),$AH$15/(1+((AK18-$AH$16)/$AH$17)^2),NA()),IF($AI$1=3,IF(AND(ISNUMBER($AH$15),ISNUMBER($AH$16),ISNUMBER($AH$17)),$AH$15*EXP((-1)*((AK18-$AH$16)/$AH$17)^2),NA()), IF($AI$1=4,IF(AND(ISNUMBER($AH$15),ISNUMBER($AH$16),ISNUMBER($AH$17),ISNUMBER($AH$18)),$AH$15*SIN((AK18*$AH$16)-$AH$17)+$AH$18,NA()),NA())))) -> 0 | AP18: =IF($AI$1=1,IF(AND(ISNUMBER($AH$15),ISNUMBER($AH$16)),$AH$15+AN18*$AH$16,NA()),IF($AI$1=2,IF(AND(ISNUMBER($AH$15),ISNUMBER($AH$16),ISNUMBER($AH$17)),$AH$15/(1+((AN18-$AH$16)/$AH$17)^2),NA()), IF($AI$1=3,IF(AND(ISNUMBER($AH$15),ISNUMBER($AH$16),ISNUMBER($AH$17)),$AH$15*EXP(-(((AN18-$AH$16)/$AH$17)^2)),NA()),IF($AI$1=4,IF(AND(ISNUMBER($AH$15),ISNUMBER($AH$16),ISNUMBER($AH$17),ISNUMBER($AH$18)),$AH$15*SIN($AH$16*AN18-$AH$17)+$AH$18,NA()),NA())))) -> 0 | AQ18: =(AP18-AO18)^2 -> 0 | AR18: =(AO18-$AO$104)^2 -> #N/A
F19: 17 | G19: =MIN(x1Data)+(MAX(x1Data)-MIN(x1Data))*(F19/100) -> 1360 | H19: =IF($D$1=1,$C$11+$B$11*G19, IF($D$1=2,$B$11*G19^#REF!,IF($D$1=3,$D$11+$C$11*G19+$B$11*(G19)^2,IF($D$1=4,$E$11+$D$11*G19+$C$11*(G19)^2+$B$11*(G19)^3,IF($D$1=5,EXP($C$11)*G19^($B$11),IF($D$1=6,EXP($C$11+G19*$B$11), NA())))))) -> #N/A | J19: =IFERROR(MIN(DA_x1data,DA_x2data)+(MAX(DA_x1data,DA_x2data)-MIN(DA_x1data,DA_x2data))*(F19/100), MIN(DA_x1data)+(MAX(DA_x1data)-MIN(DA_x1data))*(F19/100)) -> #N/A | K19: =IF($D$32=1,$B$48*J19+$C$48,IF($D$32=2,$B$48*J19^2+$C$48*J19+$D$48,IF($D$32=3,$B$48*J19^3+$C$48*J19^2+$D$48*J19+$E$48,IF($D$32=4,$B$48*J19^'Double Analysis'!$G$13,IF($D$32=5,EXP($C$48)*J19^$B$48,IF($D$32=6,EXP($C$48+J19*$B$48),NA())))))) -> #N/A | L19: =IF($D$32=1,$B$54*J19+$C$54,IF($D$32=2,$B$54*J19^2+$C$54*J19+$D$54,IF($D$32=3,$B$54*J19^3+$C$54*J19^2+$D$54*J19+$E$54,IF($D$32=4,$B$54*J19^'Double Analysis'!$G$13,IF($D$32=5,EXP($C$54)*J19^$B$54,IF($D$32=6,EXP($C$54+J19*$B$54),NA())))))) -> #N/A | N19: =IFERROR(SMALL($R$2:$R$102, ROW()-1),NA()) -> #N/A | O19: =IF(ISNUMBER(N19),INDEX(y1Data,MATCH(N19,$R$2:$R$102,0)),NA()) -> #N/A | P19: =IF($D$1=7,O19,NA()) -> #N/A | R19: =IF(Q19<>"",Q19+(0.0000000000001)*(COUNTIF($Q19:Q$102,Q19)-1),"") | Y19: =IF(ISNUMBER(T19),T19," ") | Z19: =IFERROR(SMALL($Y$2:$Y$102,ROW()-1),NA()) -> #N/A | AA19: {=IF(ISNUMBER(Z19),INDEX(DA_y1data,MATCH(Z19,$Y$2:$Y$102,0)),NA())} -> #N/A | AB19: =IF($D$32=7,AA19,NA()) -> #N/A | AC19: =IF(ISNUMBER(V19),V19," ") | AD19: =IFERROR(SMALL($AC$2:$AC$102,ROW()-1),NA()) -> #N/A | AE19: {=IF(ISNUMBER(AD19),INDEX(DA_y2data,MATCH(AD19,$AC$2:$AC$102,0)),NA())} -> #N/A | AF19: =IF($D$32=7,AE19,NA()) -> #N/A | AK19: =MIN('Manual Fitting'!$A$3:$A$32)+(MAX('Manual Fitting'!$A$3:$A$32)-MIN('Manual Fitting'!$A$3:$A$17))*(Guts!F19/100) -> 0 | AL19: =IF($AI$1=1,IF(AND(ISNUMBER($AH$15),ISNUMBER($AH$16)),$AH$15+AK19*$AH$16,NA()),IF($AI$1=2,IF(AND(ISNUMBER($AH$15),ISNUMBER($AH$16),ISNUMBER($AH$17)),$AH$15/(1+((AK19-$AH$16)/$AH$17)^2),NA()),IF($AI$1=3,IF(AND(ISNUMBER($AH$15),ISNUMBER($AH$16),ISNUMBER($AH$17)),$AH$15*EXP((-1)*((AK19-$AH$16)/$AH$17)^2),NA()), IF($AI$1=4,IF(AND(ISNUMBER($AH$15),ISNUMBER($AH$16),ISNUMBER($AH$17),ISNUMBER($AH$18)),$AH$15*SIN((AK19*$AH$16)-$AH$17)+$AH$18,NA()),NA())))) -> 0 | AP19: =IF($AI$1=1,IF(AND(ISNUMBER($AH$15),ISNUMBER($AH$16)),$AH$15+AN19*$AH$16,NA()),IF($AI$1=2,IF(AND(ISNUMBER($AH$15),ISNUMBER($AH$16),ISNUMBER($AH$17)),$AH$15/(1+((AN19-$AH$16)/$AH$17)^2),NA()), IF($AI$1=3,IF(AND(ISNUMBER($AH$15),ISNUMBER($AH$16),ISNUMBER($AH$17)),$AH$15*EXP(-(((AN19-$AH$16)/$AH$17)^2)),NA()),IF($AI$1=4,IF(AND(ISNUMBER($AH$15),ISNUMBER($AH$16),ISNUMBER($AH$17),ISNUMBER($AH$18)),$AH$15*SIN($AH$16*AN19-$AH$17)+$AH$18,NA()),NA())))) -> 0 | AQ19: =(AP19-AO19)^2 -> 0 | AR19: =(AO19-$AO$104)^2 -> #N/A
